2025-08-03 12:21:57,629 - ERROR - Необработанное исключение: NameError: name 'delete_zero_size_files' is not defined
2025-08-03 12:21:57,631 - ERROR - Трассировка стека:
Traceback (most recent call last):
  File "c:\Users\Alex\Competitions_TT_v1.1\main.py", line 743, in log_file_read
    delete_zero_size_files(directory=directory)
    ^^^^^^^^^^^^^^^^^^^^^^
NameError: name 'delete_zero_size_files' is not defined. Did you mean: 'self.delete_zero_size_files'?
