2025-08-13 11:16:18,831 - ERROR - Необработанное исключение: RuntimeError: 'cryptography' package is required for sha256_password or caching_sha2_password auth methods
2025-08-13 11:16:18,833 - ERROR - Трассировка стека:
Traceback (most recent call last):
  File "c:\Users\Alex\Competitions_TT_v1.2\main.py", line 1664, in <module>
    fir_window = StartWindow()  # Создаём объект класса ExampleApp
  File "c:\Users\Alex\Competitions_TT_v1.2\main.py", line 1223, in __init__
    conn = pymysql.connect(host='localhost', user='root', password='db_pass')
  File "C:\Users\Alex\Competitions_TT_v1.2\venv\Lib\site-packages\pymysql\connections.py", line 361, in __init__
    self.connect()
    ~~~~~~~~~~~~^^
  File "C:\Users\Alex\Competitions_TT_v1.2\venv\Lib\site-packages\pymysql\connections.py", line 669, in connect
    self._request_authentication()
    ~~~~~~~~~~~~~~~~~~~~~~~~~~~~^^
  File "C:\Users\Alex\Competitions_TT_v1.2\venv\Lib\site-packages\pymysql\connections.py", line 979, in _request_authentication
    auth_packet = _auth.caching_sha2_password_auth(self, auth_packet)
  File "C:\Users\Alex\Competitions_TT_v1.2\venv\Lib\site-packages\pymysql\_auth.py", line 267, in caching_sha2_password_auth
    data = sha2_rsa_encrypt(conn.password, conn.salt, conn.server_public_key)
  File "C:\Users\Alex\Competitions_TT_v1.2\venv\Lib\site-packages\pymysql\_auth.py", line 144, in sha2_rsa_encrypt
    raise RuntimeError(
    ...<2 lines>...
    )
RuntimeError: 'cryptography' package is required for sha256_password or caching_sha2_password auth methods
