2025-08-03 14:07:43,031 - ERROR - Необработанное исключение: IndexError: list index out of range
2025-08-03 14:07:43,033 - ERROR - Трассировка стека:
Traceback (most recent call last):
  File "c:\Users\Alex\Competitions_TT_v1.1\main.py", line 2212, in r_list_load_tableView
    fill_table_R_list()
    ~~~~~~~~~~~~~~~~~^^
  File "c:\Users\Alex\Competitions_TT_v1.1\main.py", line 2940, in fill_table_R_list
    fill_table(player_list)
    ~~~~~~~~~~^^^^^^^^^^^^^
  File "c:\Users\Alex\Competitions_TT_v1.1\main.py", line 2727, in fill_table
    item_8 = str(list(player_selected[row].values())[num_columns[7]])
                                                     ~~~~~~~~~~~^^^
IndexError: list index out of range
