2025-08-03 16:53:14,400 - ERROR - Необработанное исключение: IndexError: list index out of range
2025-08-03 16:53:14,401 - ERROR - Трассировка стека:
Traceback (most recent call last):
  File "c:\Users\Alex\Competitions_TT_v1.1\main.py", line 148, in headerData
    return self.horizontalHeaderLabels[section]
           ~~~~~~~~~~~~~~~~~~~~~~~~~~~^^^^^^^^^
IndexError: list index out of range
2025-08-03 16:53:14,796 - ERROR - Необработанное исключение: KeyError: 9
2025-08-03 16:53:14,796 - ERROR - Трассировка стека:
Traceback (most recent call last):
  File "C:\Users\Alex\Competitions_TT_v1.1\venv\Lib\site-packages\pandas\core\indexes\base.py", line 3812, in get_loc
    return self._engine.get_loc(casted_key)
           ~~~~~~~~~~~~~~~~~~~~^^^^^^^^^^^^
  File "pandas/_libs/index.pyx", line 167, in pandas._libs.index.IndexEngine.get_loc
  File "pandas/_libs/index.pyx", line 196, in pandas._libs.index.IndexEngine.get_loc
  File "pandas/_libs/hashtable_class_helper.pxi", line 2606, in pandas._libs.hashtable.Int64HashTable.get_item
  File "pandas/_libs/hashtable_class_helper.pxi", line 2630, in pandas._libs.hashtable.Int64HashTable.get_item
KeyError: 9

The above exception was the direct cause of the following exception:

Traceback (most recent call last):
  File "c:\Users\Alex\Competitions_TT_v1.1\main.py", line 167, in data
    val = str(self._data[index.row()][index.column()])
              ~~~~~~~~~~^^^^^^^^^^^^^
  File "C:\Users\Alex\Competitions_TT_v1.1\venv\Lib\site-packages\pandas\core\frame.py", line 4107, in __getitem__
    indexer = self.columns.get_loc(key)
  File "C:\Users\Alex\Competitions_TT_v1.1\venv\Lib\site-packages\pandas\core\indexes\base.py", line 3819, in get_loc
    raise KeyError(key) from err
KeyError: 9
2025-08-03 16:53:14,914 - ERROR - Необработанное исключение: KeyError: 9
2025-08-03 16:53:14,914 - ERROR - Трассировка стека:
Traceback (most recent call last):
  File "C:\Users\Alex\Competitions_TT_v1.1\venv\Lib\site-packages\pandas\core\indexes\base.py", line 3812, in get_loc
    return self._engine.get_loc(casted_key)
           ~~~~~~~~~~~~~~~~~~~~^^^^^^^^^^^^
  File "pandas/_libs/index.pyx", line 167, in pandas._libs.index.IndexEngine.get_loc
  File "pandas/_libs/index.pyx", line 196, in pandas._libs.index.IndexEngine.get_loc
  File "pandas/_libs/hashtable_class_helper.pxi", line 2606, in pandas._libs.hashtable.Int64HashTable.get_item
  File "pandas/_libs/hashtable_class_helper.pxi", line 2630, in pandas._libs.hashtable.Int64HashTable.get_item
KeyError: 9

The above exception was the direct cause of the following exception:

Traceback (most recent call last):
  File "c:\Users\Alex\Competitions_TT_v1.1\main.py", line 165, in data
    return str(self._data[index.row()][index.column()])
               ~~~~~~~~~~^^^^^^^^^^^^^
  File "C:\Users\Alex\Competitions_TT_v1.1\venv\Lib\site-packages\pandas\core\frame.py", line 4107, in __getitem__
    indexer = self.columns.get_loc(key)
  File "C:\Users\Alex\Competitions_TT_v1.1\venv\Lib\site-packages\pandas\core\indexes\base.py", line 3819, in get_loc
    raise KeyError(key) from err
KeyError: 9
2025-08-03 16:53:14,918 - ERROR - Необработанное исключение: KeyError: 9
2025-08-03 16:53:14,918 - ERROR - Трассировка стека:
Traceback (most recent call last):
  File "C:\Users\Alex\Competitions_TT_v1.1\venv\Lib\site-packages\pandas\core\indexes\base.py", line 3812, in get_loc
    return self._engine.get_loc(casted_key)
           ~~~~~~~~~~~~~~~~~~~~^^^^^^^^^^^^
  File "pandas/_libs/index.pyx", line 167, in pandas._libs.index.IndexEngine.get_loc
  File "pandas/_libs/index.pyx", line 196, in pandas._libs.index.IndexEngine.get_loc
  File "pandas/_libs/hashtable_class_helper.pxi", line 2606, in pandas._libs.hashtable.Int64HashTable.get_item
  File "pandas/_libs/hashtable_class_helper.pxi", line 2630, in pandas._libs.hashtable.Int64HashTable.get_item
KeyError: 9

The above exception was the direct cause of the following exception:

Traceback (most recent call last):
  File "c:\Users\Alex\Competitions_TT_v1.1\main.py", line 167, in data
    val = str(self._data[index.row()][index.column()])
              ~~~~~~~~~~^^^^^^^^^^^^^
  File "C:\Users\Alex\Competitions_TT_v1.1\venv\Lib\site-packages\pandas\core\frame.py", line 4107, in __getitem__
    indexer = self.columns.get_loc(key)
  File "C:\Users\Alex\Competitions_TT_v1.1\venv\Lib\site-packages\pandas\core\indexes\base.py", line 3819, in get_loc
    raise KeyError(key) from err
KeyError: 9
2025-08-03 16:53:14,924 - ERROR - Необработанное исключение: KeyError: 9
2025-08-03 16:53:14,925 - ERROR - Трассировка стека:
Traceback (most recent call last):
  File "C:\Users\Alex\Competitions_TT_v1.1\venv\Lib\site-packages\pandas\core\indexes\base.py", line 3812, in get_loc
    return self._engine.get_loc(casted_key)
           ~~~~~~~~~~~~~~~~~~~~^^^^^^^^^^^^
  File "pandas/_libs/index.pyx", line 167, in pandas._libs.index.IndexEngine.get_loc
  File "pandas/_libs/index.pyx", line 196, in pandas._libs.index.IndexEngine.get_loc
  File "pandas/_libs/hashtable_class_helper.pxi", line 2606, in pandas._libs.hashtable.Int64HashTable.get_item
  File "pandas/_libs/hashtable_class_helper.pxi", line 2630, in pandas._libs.hashtable.Int64HashTable.get_item
KeyError: 9

The above exception was the direct cause of the following exception:

Traceback (most recent call last):
  File "c:\Users\Alex\Competitions_TT_v1.1\main.py", line 165, in data
    return str(self._data[index.row()][index.column()])
               ~~~~~~~~~~^^^^^^^^^^^^^
  File "C:\Users\Alex\Competitions_TT_v1.1\venv\Lib\site-packages\pandas\core\frame.py", line 4107, in __getitem__
    indexer = self.columns.get_loc(key)
  File "C:\Users\Alex\Competitions_TT_v1.1\venv\Lib\site-packages\pandas\core\indexes\base.py", line 3819, in get_loc
    raise KeyError(key) from err
KeyError: 9
2025-08-03 16:53:14,937 - ERROR - Необработанное исключение: KeyError: 9
2025-08-03 16:53:14,937 - ERROR - Трассировка стека:
Traceback (most recent call last):
  File "C:\Users\Alex\Competitions_TT_v1.1\venv\Lib\site-packages\pandas\core\indexes\base.py", line 3812, in get_loc
    return self._engine.get_loc(casted_key)
           ~~~~~~~~~~~~~~~~~~~~^^^^^^^^^^^^
  File "pandas/_libs/index.pyx", line 167, in pandas._libs.index.IndexEngine.get_loc
  File "pandas/_libs/index.pyx", line 196, in pandas._libs.index.IndexEngine.get_loc
  File "pandas/_libs/hashtable_class_helper.pxi", line 2606, in pandas._libs.hashtable.Int64HashTable.get_item
  File "pandas/_libs/hashtable_class_helper.pxi", line 2630, in pandas._libs.hashtable.Int64HashTable.get_item
KeyError: 9

The above exception was the direct cause of the following exception:

Traceback (most recent call last):
  File "c:\Users\Alex\Competitions_TT_v1.1\main.py", line 167, in data
    val = str(self._data[index.row()][index.column()])
              ~~~~~~~~~~^^^^^^^^^^^^^
  File "C:\Users\Alex\Competitions_TT_v1.1\venv\Lib\site-packages\pandas\core\frame.py", line 4107, in __getitem__
    indexer = self.columns.get_loc(key)
  File "C:\Users\Alex\Competitions_TT_v1.1\venv\Lib\site-packages\pandas\core\indexes\base.py", line 3819, in get_loc
    raise KeyError(key) from err
KeyError: 9
2025-08-03 16:53:14,946 - ERROR - Необработанное исключение: KeyError: 9
2025-08-03 16:53:14,946 - ERROR - Трассировка стека:
Traceback (most recent call last):
  File "C:\Users\Alex\Competitions_TT_v1.1\venv\Lib\site-packages\pandas\core\indexes\base.py", line 3812, in get_loc
    return self._engine.get_loc(casted_key)
           ~~~~~~~~~~~~~~~~~~~~^^^^^^^^^^^^
  File "pandas/_libs/index.pyx", line 167, in pandas._libs.index.IndexEngine.get_loc
  File "pandas/_libs/index.pyx", line 196, in pandas._libs.index.IndexEngine.get_loc
  File "pandas/_libs/hashtable_class_helper.pxi", line 2606, in pandas._libs.hashtable.Int64HashTable.get_item
  File "pandas/_libs/hashtable_class_helper.pxi", line 2630, in pandas._libs.hashtable.Int64HashTable.get_item
KeyError: 9

The above exception was the direct cause of the following exception:

Traceback (most recent call last):
  File "c:\Users\Alex\Competitions_TT_v1.1\main.py", line 165, in data
    return str(self._data[index.row()][index.column()])
               ~~~~~~~~~~^^^^^^^^^^^^^
  File "C:\Users\Alex\Competitions_TT_v1.1\venv\Lib\site-packages\pandas\core\frame.py", line 4107, in __getitem__
    indexer = self.columns.get_loc(key)
  File "C:\Users\Alex\Competitions_TT_v1.1\venv\Lib\site-packages\pandas\core\indexes\base.py", line 3819, in get_loc
    raise KeyError(key) from err
KeyError: 9
2025-08-03 16:53:14,955 - ERROR - Необработанное исключение: KeyError: 9
2025-08-03 16:53:14,956 - ERROR - Трассировка стека:
Traceback (most recent call last):
  File "C:\Users\Alex\Competitions_TT_v1.1\venv\Lib\site-packages\pandas\core\indexes\base.py", line 3812, in get_loc
    return self._engine.get_loc(casted_key)
           ~~~~~~~~~~~~~~~~~~~~^^^^^^^^^^^^
  File "pandas/_libs/index.pyx", line 167, in pandas._libs.index.IndexEngine.get_loc
  File "pandas/_libs/index.pyx", line 196, in pandas._libs.index.IndexEngine.get_loc
  File "pandas/_libs/hashtable_class_helper.pxi", line 2606, in pandas._libs.hashtable.Int64HashTable.get_item
  File "pandas/_libs/hashtable_class_helper.pxi", line 2630, in pandas._libs.hashtable.Int64HashTable.get_item
KeyError: 9

The above exception was the direct cause of the following exception:

Traceback (most recent call last):
  File "c:\Users\Alex\Competitions_TT_v1.1\main.py", line 167, in data
    val = str(self._data[index.row()][index.column()])
              ~~~~~~~~~~^^^^^^^^^^^^^
  File "C:\Users\Alex\Competitions_TT_v1.1\venv\Lib\site-packages\pandas\core\frame.py", line 4107, in __getitem__
    indexer = self.columns.get_loc(key)
  File "C:\Users\Alex\Competitions_TT_v1.1\venv\Lib\site-packages\pandas\core\indexes\base.py", line 3819, in get_loc
    raise KeyError(key) from err
KeyError: 9
2025-08-03 16:53:14,974 - ERROR - Необработанное исключение: KeyError: 9
2025-08-03 16:53:14,978 - ERROR - Трассировка стека:
Traceback (most recent call last):
  File "C:\Users\Alex\Competitions_TT_v1.1\venv\Lib\site-packages\pandas\core\indexes\base.py", line 3812, in get_loc
    return self._engine.get_loc(casted_key)
           ~~~~~~~~~~~~~~~~~~~~^^^^^^^^^^^^
  File "pandas/_libs/index.pyx", line 167, in pandas._libs.index.IndexEngine.get_loc
  File "pandas/_libs/index.pyx", line 196, in pandas._libs.index.IndexEngine.get_loc
  File "pandas/_libs/hashtable_class_helper.pxi", line 2606, in pandas._libs.hashtable.Int64HashTable.get_item
  File "pandas/_libs/hashtable_class_helper.pxi", line 2630, in pandas._libs.hashtable.Int64HashTable.get_item
KeyError: 9

The above exception was the direct cause of the following exception:

Traceback (most recent call last):
  File "c:\Users\Alex\Competitions_TT_v1.1\main.py", line 165, in data
    return str(self._data[index.row()][index.column()])
               ~~~~~~~~~~^^^^^^^^^^^^^
  File "C:\Users\Alex\Competitions_TT_v1.1\venv\Lib\site-packages\pandas\core\frame.py", line 4107, in __getitem__
    indexer = self.columns.get_loc(key)
  File "C:\Users\Alex\Competitions_TT_v1.1\venv\Lib\site-packages\pandas\core\indexes\base.py", line 3819, in get_loc
    raise KeyError(key) from err
KeyError: 9
2025-08-03 16:53:14,981 - ERROR - Необработанное исключение: KeyError: 9
2025-08-03 16:53:14,984 - ERROR - Трассировка стека:
Traceback (most recent call last):
  File "C:\Users\Alex\Competitions_TT_v1.1\venv\Lib\site-packages\pandas\core\indexes\base.py", line 3812, in get_loc
    return self._engine.get_loc(casted_key)
           ~~~~~~~~~~~~~~~~~~~~^^^^^^^^^^^^
  File "pandas/_libs/index.pyx", line 167, in pandas._libs.index.IndexEngine.get_loc
  File "pandas/_libs/index.pyx", line 196, in pandas._libs.index.IndexEngine.get_loc
  File "pandas/_libs/hashtable_class_helper.pxi", line 2606, in pandas._libs.hashtable.Int64HashTable.get_item
  File "pandas/_libs/hashtable_class_helper.pxi", line 2630, in pandas._libs.hashtable.Int64HashTable.get_item
KeyError: 9

The above exception was the direct cause of the following exception:

Traceback (most recent call last):
  File "c:\Users\Alex\Competitions_TT_v1.1\main.py", line 167, in data
    val = str(self._data[index.row()][index.column()])
              ~~~~~~~~~~^^^^^^^^^^^^^
  File "C:\Users\Alex\Competitions_TT_v1.1\venv\Lib\site-packages\pandas\core\frame.py", line 4107, in __getitem__
    indexer = self.columns.get_loc(key)
  File "C:\Users\Alex\Competitions_TT_v1.1\venv\Lib\site-packages\pandas\core\indexes\base.py", line 3819, in get_loc
    raise KeyError(key) from err
KeyError: 9
2025-08-03 16:53:14,993 - ERROR - Необработанное исключение: KeyError: 9
2025-08-03 16:53:14,994 - ERROR - Трассировка стека:
Traceback (most recent call last):
  File "C:\Users\Alex\Competitions_TT_v1.1\venv\Lib\site-packages\pandas\core\indexes\base.py", line 3812, in get_loc
    return self._engine.get_loc(casted_key)
           ~~~~~~~~~~~~~~~~~~~~^^^^^^^^^^^^
  File "pandas/_libs/index.pyx", line 167, in pandas._libs.index.IndexEngine.get_loc
  File "pandas/_libs/index.pyx", line 196, in pandas._libs.index.IndexEngine.get_loc
  File "pandas/_libs/hashtable_class_helper.pxi", line 2606, in pandas._libs.hashtable.Int64HashTable.get_item
  File "pandas/_libs/hashtable_class_helper.pxi", line 2630, in pandas._libs.hashtable.Int64HashTable.get_item
KeyError: 9

The above exception was the direct cause of the following exception:

Traceback (most recent call last):
  File "c:\Users\Alex\Competitions_TT_v1.1\main.py", line 165, in data
    return str(self._data[index.row()][index.column()])
               ~~~~~~~~~~^^^^^^^^^^^^^
  File "C:\Users\Alex\Competitions_TT_v1.1\venv\Lib\site-packages\pandas\core\frame.py", line 4107, in __getitem__
    indexer = self.columns.get_loc(key)
  File "C:\Users\Alex\Competitions_TT_v1.1\venv\Lib\site-packages\pandas\core\indexes\base.py", line 3819, in get_loc
    raise KeyError(key) from err
KeyError: 9
2025-08-03 16:53:15,002 - ERROR - Необработанное исключение: KeyError: 9
2025-08-03 16:53:15,004 - ERROR - Трассировка стека:
Traceback (most recent call last):
  File "C:\Users\Alex\Competitions_TT_v1.1\venv\Lib\site-packages\pandas\core\indexes\base.py", line 3812, in get_loc
    return self._engine.get_loc(casted_key)
           ~~~~~~~~~~~~~~~~~~~~^^^^^^^^^^^^
  File "pandas/_libs/index.pyx", line 167, in pandas._libs.index.IndexEngine.get_loc
  File "pandas/_libs/index.pyx", line 196, in pandas._libs.index.IndexEngine.get_loc
  File "pandas/_libs/hashtable_class_helper.pxi", line 2606, in pandas._libs.hashtable.Int64HashTable.get_item
  File "pandas/_libs/hashtable_class_helper.pxi", line 2630, in pandas._libs.hashtable.Int64HashTable.get_item
KeyError: 9

The above exception was the direct cause of the following exception:

Traceback (most recent call last):
  File "c:\Users\Alex\Competitions_TT_v1.1\main.py", line 167, in data
    val = str(self._data[index.row()][index.column()])
              ~~~~~~~~~~^^^^^^^^^^^^^
  File "C:\Users\Alex\Competitions_TT_v1.1\venv\Lib\site-packages\pandas\core\frame.py", line 4107, in __getitem__
    indexer = self.columns.get_loc(key)
  File "C:\Users\Alex\Competitions_TT_v1.1\venv\Lib\site-packages\pandas\core\indexes\base.py", line 3819, in get_loc
    raise KeyError(key) from err
KeyError: 9
2025-08-03 16:53:15,009 - ERROR - Необработанное исключение: KeyError: 9
2025-08-03 16:53:15,010 - ERROR - Трассировка стека:
Traceback (most recent call last):
  File "C:\Users\Alex\Competitions_TT_v1.1\venv\Lib\site-packages\pandas\core\indexes\base.py", line 3812, in get_loc
    return self._engine.get_loc(casted_key)
           ~~~~~~~~~~~~~~~~~~~~^^^^^^^^^^^^
  File "pandas/_libs/index.pyx", line 167, in pandas._libs.index.IndexEngine.get_loc
  File "pandas/_libs/index.pyx", line 196, in pandas._libs.index.IndexEngine.get_loc
  File "pandas/_libs/hashtable_class_helper.pxi", line 2606, in pandas._libs.hashtable.Int64HashTable.get_item
  File "pandas/_libs/hashtable_class_helper.pxi", line 2630, in pandas._libs.hashtable.Int64HashTable.get_item
KeyError: 9

The above exception was the direct cause of the following exception:

Traceback (most recent call last):
  File "c:\Users\Alex\Competitions_TT_v1.1\main.py", line 165, in data
    return str(self._data[index.row()][index.column()])
               ~~~~~~~~~~^^^^^^^^^^^^^
  File "C:\Users\Alex\Competitions_TT_v1.1\venv\Lib\site-packages\pandas\core\frame.py", line 4107, in __getitem__
    indexer = self.columns.get_loc(key)
  File "C:\Users\Alex\Competitions_TT_v1.1\venv\Lib\site-packages\pandas\core\indexes\base.py", line 3819, in get_loc
    raise KeyError(key) from err
KeyError: 9
2025-08-03 16:53:15,014 - ERROR - Необработанное исключение: KeyError: 9
2025-08-03 16:53:15,014 - ERROR - Трассировка стека:
Traceback (most recent call last):
  File "C:\Users\Alex\Competitions_TT_v1.1\venv\Lib\site-packages\pandas\core\indexes\base.py", line 3812, in get_loc
    return self._engine.get_loc(casted_key)
           ~~~~~~~~~~~~~~~~~~~~^^^^^^^^^^^^
  File "pandas/_libs/index.pyx", line 167, in pandas._libs.index.IndexEngine.get_loc
  File "pandas/_libs/index.pyx", line 196, in pandas._libs.index.IndexEngine.get_loc
  File "pandas/_libs/hashtable_class_helper.pxi", line 2606, in pandas._libs.hashtable.Int64HashTable.get_item
  File "pandas/_libs/hashtable_class_helper.pxi", line 2630, in pandas._libs.hashtable.Int64HashTable.get_item
KeyError: 9

The above exception was the direct cause of the following exception:

Traceback (most recent call last):
  File "c:\Users\Alex\Competitions_TT_v1.1\main.py", line 167, in data
    val = str(self._data[index.row()][index.column()])
              ~~~~~~~~~~^^^^^^^^^^^^^
  File "C:\Users\Alex\Competitions_TT_v1.1\venv\Lib\site-packages\pandas\core\frame.py", line 4107, in __getitem__
    indexer = self.columns.get_loc(key)
  File "C:\Users\Alex\Competitions_TT_v1.1\venv\Lib\site-packages\pandas\core\indexes\base.py", line 3819, in get_loc
    raise KeyError(key) from err
KeyError: 9
2025-08-03 16:53:15,024 - ERROR - Необработанное исключение: KeyError: 9
2025-08-03 16:53:15,025 - ERROR - Трассировка стека:
Traceback (most recent call last):
  File "C:\Users\Alex\Competitions_TT_v1.1\venv\Lib\site-packages\pandas\core\indexes\base.py", line 3812, in get_loc
    return self._engine.get_loc(casted_key)
           ~~~~~~~~~~~~~~~~~~~~^^^^^^^^^^^^
  File "pandas/_libs/index.pyx", line 167, in pandas._libs.index.IndexEngine.get_loc
  File "pandas/_libs/index.pyx", line 196, in pandas._libs.index.IndexEngine.get_loc
  File "pandas/_libs/hashtable_class_helper.pxi", line 2606, in pandas._libs.hashtable.Int64HashTable.get_item
  File "pandas/_libs/hashtable_class_helper.pxi", line 2630, in pandas._libs.hashtable.Int64HashTable.get_item
KeyError: 9

The above exception was the direct cause of the following exception:

Traceback (most recent call last):
  File "c:\Users\Alex\Competitions_TT_v1.1\main.py", line 165, in data
    return str(self._data[index.row()][index.column()])
               ~~~~~~~~~~^^^^^^^^^^^^^
  File "C:\Users\Alex\Competitions_TT_v1.1\venv\Lib\site-packages\pandas\core\frame.py", line 4107, in __getitem__
    indexer = self.columns.get_loc(key)
  File "C:\Users\Alex\Competitions_TT_v1.1\venv\Lib\site-packages\pandas\core\indexes\base.py", line 3819, in get_loc
    raise KeyError(key) from err
KeyError: 9
2025-08-03 16:53:15,033 - ERROR - Необработанное исключение: KeyError: 9
2025-08-03 16:53:15,034 - ERROR - Трассировка стека:
Traceback (most recent call last):
  File "C:\Users\Alex\Competitions_TT_v1.1\venv\Lib\site-packages\pandas\core\indexes\base.py", line 3812, in get_loc
    return self._engine.get_loc(casted_key)
           ~~~~~~~~~~~~~~~~~~~~^^^^^^^^^^^^
  File "pandas/_libs/index.pyx", line 167, in pandas._libs.index.IndexEngine.get_loc
  File "pandas/_libs/index.pyx", line 196, in pandas._libs.index.IndexEngine.get_loc
  File "pandas/_libs/hashtable_class_helper.pxi", line 2606, in pandas._libs.hashtable.Int64HashTable.get_item
  File "pandas/_libs/hashtable_class_helper.pxi", line 2630, in pandas._libs.hashtable.Int64HashTable.get_item
KeyError: 9

The above exception was the direct cause of the following exception:

Traceback (most recent call last):
  File "c:\Users\Alex\Competitions_TT_v1.1\main.py", line 167, in data
    val = str(self._data[index.row()][index.column()])
              ~~~~~~~~~~^^^^^^^^^^^^^
  File "C:\Users\Alex\Competitions_TT_v1.1\venv\Lib\site-packages\pandas\core\frame.py", line 4107, in __getitem__
    indexer = self.columns.get_loc(key)
  File "C:\Users\Alex\Competitions_TT_v1.1\venv\Lib\site-packages\pandas\core\indexes\base.py", line 3819, in get_loc
    raise KeyError(key) from err
KeyError: 9
2025-08-03 16:53:15,040 - ERROR - Необработанное исключение: KeyError: 9
2025-08-03 16:53:15,041 - ERROR - Трассировка стека:
Traceback (most recent call last):
  File "C:\Users\Alex\Competitions_TT_v1.1\venv\Lib\site-packages\pandas\core\indexes\base.py", line 3812, in get_loc
    return self._engine.get_loc(casted_key)
           ~~~~~~~~~~~~~~~~~~~~^^^^^^^^^^^^
  File "pandas/_libs/index.pyx", line 167, in pandas._libs.index.IndexEngine.get_loc
  File "pandas/_libs/index.pyx", line 196, in pandas._libs.index.IndexEngine.get_loc
  File "pandas/_libs/hashtable_class_helper.pxi", line 2606, in pandas._libs.hashtable.Int64HashTable.get_item
  File "pandas/_libs/hashtable_class_helper.pxi", line 2630, in pandas._libs.hashtable.Int64HashTable.get_item
KeyError: 9

The above exception was the direct cause of the following exception:

Traceback (most recent call last):
  File "c:\Users\Alex\Competitions_TT_v1.1\main.py", line 165, in data
    return str(self._data[index.row()][index.column()])
               ~~~~~~~~~~^^^^^^^^^^^^^
  File "C:\Users\Alex\Competitions_TT_v1.1\venv\Lib\site-packages\pandas\core\frame.py", line 4107, in __getitem__
    indexer = self.columns.get_loc(key)
  File "C:\Users\Alex\Competitions_TT_v1.1\venv\Lib\site-packages\pandas\core\indexes\base.py", line 3819, in get_loc
    raise KeyError(key) from err
KeyError: 9
2025-08-03 16:53:15,243 - ERROR - Необработанное исключение: KeyError: 9
2025-08-03 16:53:15,244 - ERROR - Трассировка стека:
Traceback (most recent call last):
  File "C:\Users\Alex\Competitions_TT_v1.1\venv\Lib\site-packages\pandas\core\indexes\base.py", line 3812, in get_loc
    return self._engine.get_loc(casted_key)
           ~~~~~~~~~~~~~~~~~~~~^^^^^^^^^^^^
  File "pandas/_libs/index.pyx", line 167, in pandas._libs.index.IndexEngine.get_loc
  File "pandas/_libs/index.pyx", line 196, in pandas._libs.index.IndexEngine.get_loc
  File "pandas/_libs/hashtable_class_helper.pxi", line 2606, in pandas._libs.hashtable.Int64HashTable.get_item
  File "pandas/_libs/hashtable_class_helper.pxi", line 2630, in pandas._libs.hashtable.Int64HashTable.get_item
KeyError: 9

The above exception was the direct cause of the following exception:

Traceback (most recent call last):
  File "c:\Users\Alex\Competitions_TT_v1.1\main.py", line 167, in data
    val = str(self._data[index.row()][index.column()])
              ~~~~~~~~~~^^^^^^^^^^^^^
  File "C:\Users\Alex\Competitions_TT_v1.1\venv\Lib\site-packages\pandas\core\frame.py", line 4107, in __getitem__
    indexer = self.columns.get_loc(key)
  File "C:\Users\Alex\Competitions_TT_v1.1\venv\Lib\site-packages\pandas\core\indexes\base.py", line 3819, in get_loc
    raise KeyError(key) from err
KeyError: 9
2025-08-03 16:53:15,247 - ERROR - Необработанное исключение: KeyError: 9
2025-08-03 16:53:15,248 - ERROR - Трассировка стека:
Traceback (most recent call last):
  File "C:\Users\Alex\Competitions_TT_v1.1\venv\Lib\site-packages\pandas\core\indexes\base.py", line 3812, in get_loc
    return self._engine.get_loc(casted_key)
           ~~~~~~~~~~~~~~~~~~~~^^^^^^^^^^^^
  File "pandas/_libs/index.pyx", line 167, in pandas._libs.index.IndexEngine.get_loc
  File "pandas/_libs/index.pyx", line 196, in pandas._libs.index.IndexEngine.get_loc
  File "pandas/_libs/hashtable_class_helper.pxi", line 2606, in pandas._libs.hashtable.Int64HashTable.get_item
  File "pandas/_libs/hashtable_class_helper.pxi", line 2630, in pandas._libs.hashtable.Int64HashTable.get_item
KeyError: 9

The above exception was the direct cause of the following exception:

Traceback (most recent call last):
  File "c:\Users\Alex\Competitions_TT_v1.1\main.py", line 165, in data
    return str(self._data[index.row()][index.column()])
               ~~~~~~~~~~^^^^^^^^^^^^^
  File "C:\Users\Alex\Competitions_TT_v1.1\venv\Lib\site-packages\pandas\core\frame.py", line 4107, in __getitem__
    indexer = self.columns.get_loc(key)
  File "C:\Users\Alex\Competitions_TT_v1.1\venv\Lib\site-packages\pandas\core\indexes\base.py", line 3819, in get_loc
    raise KeyError(key) from err
KeyError: 9
2025-08-03 16:53:15,252 - ERROR - Необработанное исключение: KeyError: 9
2025-08-03 16:53:15,252 - ERROR - Трассировка стека:
Traceback (most recent call last):
  File "C:\Users\Alex\Competitions_TT_v1.1\venv\Lib\site-packages\pandas\core\indexes\base.py", line 3812, in get_loc
    return self._engine.get_loc(casted_key)
           ~~~~~~~~~~~~~~~~~~~~^^^^^^^^^^^^
  File "pandas/_libs/index.pyx", line 167, in pandas._libs.index.IndexEngine.get_loc
  File "pandas/_libs/index.pyx", line 196, in pandas._libs.index.IndexEngine.get_loc
  File "pandas/_libs/hashtable_class_helper.pxi", line 2606, in pandas._libs.hashtable.Int64HashTable.get_item
  File "pandas/_libs/hashtable_class_helper.pxi", line 2630, in pandas._libs.hashtable.Int64HashTable.get_item
KeyError: 9

The above exception was the direct cause of the following exception:

Traceback (most recent call last):
  File "c:\Users\Alex\Competitions_TT_v1.1\main.py", line 167, in data
    val = str(self._data[index.row()][index.column()])
              ~~~~~~~~~~^^^^^^^^^^^^^
  File "C:\Users\Alex\Competitions_TT_v1.1\venv\Lib\site-packages\pandas\core\frame.py", line 4107, in __getitem__
    indexer = self.columns.get_loc(key)
  File "C:\Users\Alex\Competitions_TT_v1.1\venv\Lib\site-packages\pandas\core\indexes\base.py", line 3819, in get_loc
    raise KeyError(key) from err
KeyError: 9
2025-08-03 16:53:15,258 - ERROR - Необработанное исключение: KeyError: 9
2025-08-03 16:53:15,260 - ERROR - Трассировка стека:
Traceback (most recent call last):
  File "C:\Users\Alex\Competitions_TT_v1.1\venv\Lib\site-packages\pandas\core\indexes\base.py", line 3812, in get_loc
    return self._engine.get_loc(casted_key)
           ~~~~~~~~~~~~~~~~~~~~^^^^^^^^^^^^
  File "pandas/_libs/index.pyx", line 167, in pandas._libs.index.IndexEngine.get_loc
  File "pandas/_libs/index.pyx", line 196, in pandas._libs.index.IndexEngine.get_loc
  File "pandas/_libs/hashtable_class_helper.pxi", line 2606, in pandas._libs.hashtable.Int64HashTable.get_item
  File "pandas/_libs/hashtable_class_helper.pxi", line 2630, in pandas._libs.hashtable.Int64HashTable.get_item
KeyError: 9

The above exception was the direct cause of the following exception:

Traceback (most recent call last):
  File "c:\Users\Alex\Competitions_TT_v1.1\main.py", line 165, in data
    return str(self._data[index.row()][index.column()])
               ~~~~~~~~~~^^^^^^^^^^^^^
  File "C:\Users\Alex\Competitions_TT_v1.1\venv\Lib\site-packages\pandas\core\frame.py", line 4107, in __getitem__
    indexer = self.columns.get_loc(key)
  File "C:\Users\Alex\Competitions_TT_v1.1\venv\Lib\site-packages\pandas\core\indexes\base.py", line 3819, in get_loc
    raise KeyError(key) from err
KeyError: 9
2025-08-03 16:53:15,265 - ERROR - Необработанное исключение: KeyError: 9
2025-08-03 16:53:15,266 - ERROR - Трассировка стека:
Traceback (most recent call last):
  File "C:\Users\Alex\Competitions_TT_v1.1\venv\Lib\site-packages\pandas\core\indexes\base.py", line 3812, in get_loc
    return self._engine.get_loc(casted_key)
           ~~~~~~~~~~~~~~~~~~~~^^^^^^^^^^^^
  File "pandas/_libs/index.pyx", line 167, in pandas._libs.index.IndexEngine.get_loc
  File "pandas/_libs/index.pyx", line 196, in pandas._libs.index.IndexEngine.get_loc
  File "pandas/_libs/hashtable_class_helper.pxi", line 2606, in pandas._libs.hashtable.Int64HashTable.get_item
  File "pandas/_libs/hashtable_class_helper.pxi", line 2630, in pandas._libs.hashtable.Int64HashTable.get_item
KeyError: 9

The above exception was the direct cause of the following exception:

Traceback (most recent call last):
  File "c:\Users\Alex\Competitions_TT_v1.1\main.py", line 167, in data
    val = str(self._data[index.row()][index.column()])
              ~~~~~~~~~~^^^^^^^^^^^^^
  File "C:\Users\Alex\Competitions_TT_v1.1\venv\Lib\site-packages\pandas\core\frame.py", line 4107, in __getitem__
    indexer = self.columns.get_loc(key)
  File "C:\Users\Alex\Competitions_TT_v1.1\venv\Lib\site-packages\pandas\core\indexes\base.py", line 3819, in get_loc
    raise KeyError(key) from err
KeyError: 9
2025-08-03 16:53:15,277 - ERROR - Необработанное исключение: KeyError: 9
2025-08-03 16:53:15,277 - ERROR - Трассировка стека:
Traceback (most recent call last):
  File "C:\Users\Alex\Competitions_TT_v1.1\venv\Lib\site-packages\pandas\core\indexes\base.py", line 3812, in get_loc
    return self._engine.get_loc(casted_key)
           ~~~~~~~~~~~~~~~~~~~~^^^^^^^^^^^^
  File "pandas/_libs/index.pyx", line 167, in pandas._libs.index.IndexEngine.get_loc
  File "pandas/_libs/index.pyx", line 196, in pandas._libs.index.IndexEngine.get_loc
  File "pandas/_libs/hashtable_class_helper.pxi", line 2606, in pandas._libs.hashtable.Int64HashTable.get_item
  File "pandas/_libs/hashtable_class_helper.pxi", line 2630, in pandas._libs.hashtable.Int64HashTable.get_item
KeyError: 9

The above exception was the direct cause of the following exception:

Traceback (most recent call last):
  File "c:\Users\Alex\Competitions_TT_v1.1\main.py", line 165, in data
    return str(self._data[index.row()][index.column()])
               ~~~~~~~~~~^^^^^^^^^^^^^
  File "C:\Users\Alex\Competitions_TT_v1.1\venv\Lib\site-packages\pandas\core\frame.py", line 4107, in __getitem__
    indexer = self.columns.get_loc(key)
  File "C:\Users\Alex\Competitions_TT_v1.1\venv\Lib\site-packages\pandas\core\indexes\base.py", line 3819, in get_loc
    raise KeyError(key) from err
KeyError: 9
2025-08-03 16:53:15,281 - ERROR - Необработанное исключение: KeyError: 9
2025-08-03 16:53:15,281 - ERROR - Трассировка стека:
Traceback (most recent call last):
  File "C:\Users\Alex\Competitions_TT_v1.1\venv\Lib\site-packages\pandas\core\indexes\base.py", line 3812, in get_loc
    return self._engine.get_loc(casted_key)
           ~~~~~~~~~~~~~~~~~~~~^^^^^^^^^^^^
  File "pandas/_libs/index.pyx", line 167, in pandas._libs.index.IndexEngine.get_loc
  File "pandas/_libs/index.pyx", line 196, in pandas._libs.index.IndexEngine.get_loc
  File "pandas/_libs/hashtable_class_helper.pxi", line 2606, in pandas._libs.hashtable.Int64HashTable.get_item
  File "pandas/_libs/hashtable_class_helper.pxi", line 2630, in pandas._libs.hashtable.Int64HashTable.get_item
KeyError: 9

The above exception was the direct cause of the following exception:

Traceback (most recent call last):
  File "c:\Users\Alex\Competitions_TT_v1.1\main.py", line 167, in data
    val = str(self._data[index.row()][index.column()])
              ~~~~~~~~~~^^^^^^^^^^^^^
  File "C:\Users\Alex\Competitions_TT_v1.1\venv\Lib\site-packages\pandas\core\frame.py", line 4107, in __getitem__
    indexer = self.columns.get_loc(key)
  File "C:\Users\Alex\Competitions_TT_v1.1\venv\Lib\site-packages\pandas\core\indexes\base.py", line 3819, in get_loc
    raise KeyError(key) from err
KeyError: 9
2025-08-03 16:53:15,291 - ERROR - Необработанное исключение: KeyError: 9
2025-08-03 16:53:15,292 - ERROR - Трассировка стека:
Traceback (most recent call last):
  File "C:\Users\Alex\Competitions_TT_v1.1\venv\Lib\site-packages\pandas\core\indexes\base.py", line 3812, in get_loc
    return self._engine.get_loc(casted_key)
           ~~~~~~~~~~~~~~~~~~~~^^^^^^^^^^^^
  File "pandas/_libs/index.pyx", line 167, in pandas._libs.index.IndexEngine.get_loc
  File "pandas/_libs/index.pyx", line 196, in pandas._libs.index.IndexEngine.get_loc
  File "pandas/_libs/hashtable_class_helper.pxi", line 2606, in pandas._libs.hashtable.Int64HashTable.get_item
  File "pandas/_libs/hashtable_class_helper.pxi", line 2630, in pandas._libs.hashtable.Int64HashTable.get_item
KeyError: 9

The above exception was the direct cause of the following exception:

Traceback (most recent call last):
  File "c:\Users\Alex\Competitions_TT_v1.1\main.py", line 165, in data
    return str(self._data[index.row()][index.column()])
               ~~~~~~~~~~^^^^^^^^^^^^^
  File "C:\Users\Alex\Competitions_TT_v1.1\venv\Lib\site-packages\pandas\core\frame.py", line 4107, in __getitem__
    indexer = self.columns.get_loc(key)
  File "C:\Users\Alex\Competitions_TT_v1.1\venv\Lib\site-packages\pandas\core\indexes\base.py", line 3819, in get_loc
    raise KeyError(key) from err
KeyError: 9
2025-08-03 16:53:15,298 - ERROR - Необработанное исключение: KeyError: 9
2025-08-03 16:53:15,298 - ERROR - Трассировка стека:
Traceback (most recent call last):
  File "C:\Users\Alex\Competitions_TT_v1.1\venv\Lib\site-packages\pandas\core\indexes\base.py", line 3812, in get_loc
    return self._engine.get_loc(casted_key)
           ~~~~~~~~~~~~~~~~~~~~^^^^^^^^^^^^
  File "pandas/_libs/index.pyx", line 167, in pandas._libs.index.IndexEngine.get_loc
  File "pandas/_libs/index.pyx", line 196, in pandas._libs.index.IndexEngine.get_loc
  File "pandas/_libs/hashtable_class_helper.pxi", line 2606, in pandas._libs.hashtable.Int64HashTable.get_item
  File "pandas/_libs/hashtable_class_helper.pxi", line 2630, in pandas._libs.hashtable.Int64HashTable.get_item
KeyError: 9

The above exception was the direct cause of the following exception:

Traceback (most recent call last):
  File "c:\Users\Alex\Competitions_TT_v1.1\main.py", line 167, in data
    val = str(self._data[index.row()][index.column()])
              ~~~~~~~~~~^^^^^^^^^^^^^
  File "C:\Users\Alex\Competitions_TT_v1.1\venv\Lib\site-packages\pandas\core\frame.py", line 4107, in __getitem__
    indexer = self.columns.get_loc(key)
  File "C:\Users\Alex\Competitions_TT_v1.1\venv\Lib\site-packages\pandas\core\indexes\base.py", line 3819, in get_loc
    raise KeyError(key) from err
KeyError: 9
2025-08-03 16:53:15,309 - ERROR - Необработанное исключение: KeyError: 9
2025-08-03 16:53:15,309 - ERROR - Трассировка стека:
Traceback (most recent call last):
  File "C:\Users\Alex\Competitions_TT_v1.1\venv\Lib\site-packages\pandas\core\indexes\base.py", line 3812, in get_loc
    return self._engine.get_loc(casted_key)
           ~~~~~~~~~~~~~~~~~~~~^^^^^^^^^^^^
  File "pandas/_libs/index.pyx", line 167, in pandas._libs.index.IndexEngine.get_loc
  File "pandas/_libs/index.pyx", line 196, in pandas._libs.index.IndexEngine.get_loc
  File "pandas/_libs/hashtable_class_helper.pxi", line 2606, in pandas._libs.hashtable.Int64HashTable.get_item
  File "pandas/_libs/hashtable_class_helper.pxi", line 2630, in pandas._libs.hashtable.Int64HashTable.get_item
KeyError: 9

The above exception was the direct cause of the following exception:

Traceback (most recent call last):
  File "c:\Users\Alex\Competitions_TT_v1.1\main.py", line 165, in data
    return str(self._data[index.row()][index.column()])
               ~~~~~~~~~~^^^^^^^^^^^^^
  File "C:\Users\Alex\Competitions_TT_v1.1\venv\Lib\site-packages\pandas\core\frame.py", line 4107, in __getitem__
    indexer = self.columns.get_loc(key)
  File "C:\Users\Alex\Competitions_TT_v1.1\venv\Lib\site-packages\pandas\core\indexes\base.py", line 3819, in get_loc
    raise KeyError(key) from err
KeyError: 9
2025-08-03 16:53:15,314 - ERROR - Необработанное исключение: KeyError: 9
2025-08-03 16:53:15,315 - ERROR - Трассировка стека:
Traceback (most recent call last):
  File "C:\Users\Alex\Competitions_TT_v1.1\venv\Lib\site-packages\pandas\core\indexes\base.py", line 3812, in get_loc
    return self._engine.get_loc(casted_key)
           ~~~~~~~~~~~~~~~~~~~~^^^^^^^^^^^^
  File "pandas/_libs/index.pyx", line 167, in pandas._libs.index.IndexEngine.get_loc
  File "pandas/_libs/index.pyx", line 196, in pandas._libs.index.IndexEngine.get_loc
  File "pandas/_libs/hashtable_class_helper.pxi", line 2606, in pandas._libs.hashtable.Int64HashTable.get_item
  File "pandas/_libs/hashtable_class_helper.pxi", line 2630, in pandas._libs.hashtable.Int64HashTable.get_item
KeyError: 9

The above exception was the direct cause of the following exception:

Traceback (most recent call last):
  File "c:\Users\Alex\Competitions_TT_v1.1\main.py", line 167, in data
    val = str(self._data[index.row()][index.column()])
              ~~~~~~~~~~^^^^^^^^^^^^^
  File "C:\Users\Alex\Competitions_TT_v1.1\venv\Lib\site-packages\pandas\core\frame.py", line 4107, in __getitem__
    indexer = self.columns.get_loc(key)
  File "C:\Users\Alex\Competitions_TT_v1.1\venv\Lib\site-packages\pandas\core\indexes\base.py", line 3819, in get_loc
    raise KeyError(key) from err
KeyError: 9
2025-08-03 16:53:15,347 - ERROR - Необработанное исключение: KeyError: 9
2025-08-03 16:53:15,348 - ERROR - Трассировка стека:
Traceback (most recent call last):
  File "C:\Users\Alex\Competitions_TT_v1.1\venv\Lib\site-packages\pandas\core\indexes\base.py", line 3812, in get_loc
    return self._engine.get_loc(casted_key)
           ~~~~~~~~~~~~~~~~~~~~^^^^^^^^^^^^
  File "pandas/_libs/index.pyx", line 167, in pandas._libs.index.IndexEngine.get_loc
  File "pandas/_libs/index.pyx", line 196, in pandas._libs.index.IndexEngine.get_loc
  File "pandas/_libs/hashtable_class_helper.pxi", line 2606, in pandas._libs.hashtable.Int64HashTable.get_item
  File "pandas/_libs/hashtable_class_helper.pxi", line 2630, in pandas._libs.hashtable.Int64HashTable.get_item
KeyError: 9

The above exception was the direct cause of the following exception:

Traceback (most recent call last):
  File "c:\Users\Alex\Competitions_TT_v1.1\main.py", line 165, in data
    return str(self._data[index.row()][index.column()])
               ~~~~~~~~~~^^^^^^^^^^^^^
  File "C:\Users\Alex\Competitions_TT_v1.1\venv\Lib\site-packages\pandas\core\frame.py", line 4107, in __getitem__
    indexer = self.columns.get_loc(key)
  File "C:\Users\Alex\Competitions_TT_v1.1\venv\Lib\site-packages\pandas\core\indexes\base.py", line 3819, in get_loc
    raise KeyError(key) from err
KeyError: 9
2025-08-03 16:53:15,386 - ERROR - Необработанное исключение: KeyError: 9
2025-08-03 16:53:15,393 - ERROR - Трассировка стека:
Traceback (most recent call last):
  File "C:\Users\Alex\Competitions_TT_v1.1\venv\Lib\site-packages\pandas\core\indexes\base.py", line 3812, in get_loc
    return self._engine.get_loc(casted_key)
           ~~~~~~~~~~~~~~~~~~~~^^^^^^^^^^^^
  File "pandas/_libs/index.pyx", line 167, in pandas._libs.index.IndexEngine.get_loc
  File "pandas/_libs/index.pyx", line 196, in pandas._libs.index.IndexEngine.get_loc
  File "pandas/_libs/hashtable_class_helper.pxi", line 2606, in pandas._libs.hashtable.Int64HashTable.get_item
  File "pandas/_libs/hashtable_class_helper.pxi", line 2630, in pandas._libs.hashtable.Int64HashTable.get_item
KeyError: 9

The above exception was the direct cause of the following exception:

Traceback (most recent call last):
  File "c:\Users\Alex\Competitions_TT_v1.1\main.py", line 167, in data
    val = str(self._data[index.row()][index.column()])
              ~~~~~~~~~~^^^^^^^^^^^^^
  File "C:\Users\Alex\Competitions_TT_v1.1\venv\Lib\site-packages\pandas\core\frame.py", line 4107, in __getitem__
    indexer = self.columns.get_loc(key)
  File "C:\Users\Alex\Competitions_TT_v1.1\venv\Lib\site-packages\pandas\core\indexes\base.py", line 3819, in get_loc
    raise KeyError(key) from err
KeyError: 9
2025-08-03 16:53:15,400 - ERROR - Необработанное исключение: KeyError: 9
2025-08-03 16:53:15,414 - ERROR - Трассировка стека:
Traceback (most recent call last):
  File "C:\Users\Alex\Competitions_TT_v1.1\venv\Lib\site-packages\pandas\core\indexes\base.py", line 3812, in get_loc
    return self._engine.get_loc(casted_key)
           ~~~~~~~~~~~~~~~~~~~~^^^^^^^^^^^^
  File "pandas/_libs/index.pyx", line 167, in pandas._libs.index.IndexEngine.get_loc
  File "pandas/_libs/index.pyx", line 196, in pandas._libs.index.IndexEngine.get_loc
  File "pandas/_libs/hashtable_class_helper.pxi", line 2606, in pandas._libs.hashtable.Int64HashTable.get_item
  File "pandas/_libs/hashtable_class_helper.pxi", line 2630, in pandas._libs.hashtable.Int64HashTable.get_item
KeyError: 9

The above exception was the direct cause of the following exception:

Traceback (most recent call last):
  File "c:\Users\Alex\Competitions_TT_v1.1\main.py", line 165, in data
    return str(self._data[index.row()][index.column()])
               ~~~~~~~~~~^^^^^^^^^^^^^
  File "C:\Users\Alex\Competitions_TT_v1.1\venv\Lib\site-packages\pandas\core\frame.py", line 4107, in __getitem__
    indexer = self.columns.get_loc(key)
  File "C:\Users\Alex\Competitions_TT_v1.1\venv\Lib\site-packages\pandas\core\indexes\base.py", line 3819, in get_loc
    raise KeyError(key) from err
KeyError: 9
2025-08-03 16:53:15,477 - ERROR - Необработанное исключение: KeyError: 9
2025-08-03 16:53:15,478 - ERROR - Трассировка стека:
Traceback (most recent call last):
  File "C:\Users\Alex\Competitions_TT_v1.1\venv\Lib\site-packages\pandas\core\indexes\base.py", line 3812, in get_loc
    return self._engine.get_loc(casted_key)
           ~~~~~~~~~~~~~~~~~~~~^^^^^^^^^^^^
  File "pandas/_libs/index.pyx", line 167, in pandas._libs.index.IndexEngine.get_loc
  File "pandas/_libs/index.pyx", line 196, in pandas._libs.index.IndexEngine.get_loc
  File "pandas/_libs/hashtable_class_helper.pxi", line 2606, in pandas._libs.hashtable.Int64HashTable.get_item
  File "pandas/_libs/hashtable_class_helper.pxi", line 2630, in pandas._libs.hashtable.Int64HashTable.get_item
KeyError: 9

The above exception was the direct cause of the following exception:

Traceback (most recent call last):
  File "c:\Users\Alex\Competitions_TT_v1.1\main.py", line 167, in data
    val = str(self._data[index.row()][index.column()])
              ~~~~~~~~~~^^^^^^^^^^^^^
  File "C:\Users\Alex\Competitions_TT_v1.1\venv\Lib\site-packages\pandas\core\frame.py", line 4107, in __getitem__
    indexer = self.columns.get_loc(key)
  File "C:\Users\Alex\Competitions_TT_v1.1\venv\Lib\site-packages\pandas\core\indexes\base.py", line 3819, in get_loc
    raise KeyError(key) from err
KeyError: 9
2025-08-03 16:53:15,484 - ERROR - Необработанное исключение: KeyError: 9
2025-08-03 16:53:15,485 - ERROR - Трассировка стека:
Traceback (most recent call last):
  File "C:\Users\Alex\Competitions_TT_v1.1\venv\Lib\site-packages\pandas\core\indexes\base.py", line 3812, in get_loc
    return self._engine.get_loc(casted_key)
           ~~~~~~~~~~~~~~~~~~~~^^^^^^^^^^^^
  File "pandas/_libs/index.pyx", line 167, in pandas._libs.index.IndexEngine.get_loc
  File "pandas/_libs/index.pyx", line 196, in pandas._libs.index.IndexEngine.get_loc
  File "pandas/_libs/hashtable_class_helper.pxi", line 2606, in pandas._libs.hashtable.Int64HashTable.get_item
  File "pandas/_libs/hashtable_class_helper.pxi", line 2630, in pandas._libs.hashtable.Int64HashTable.get_item
KeyError: 9

The above exception was the direct cause of the following exception:

Traceback (most recent call last):
  File "c:\Users\Alex\Competitions_TT_v1.1\main.py", line 165, in data
    return str(self._data[index.row()][index.column()])
               ~~~~~~~~~~^^^^^^^^^^^^^
  File "C:\Users\Alex\Competitions_TT_v1.1\venv\Lib\site-packages\pandas\core\frame.py", line 4107, in __getitem__
    indexer = self.columns.get_loc(key)
  File "C:\Users\Alex\Competitions_TT_v1.1\venv\Lib\site-packages\pandas\core\indexes\base.py", line 3819, in get_loc
    raise KeyError(key) from err
KeyError: 9
2025-08-03 16:53:21,422 - ERROR - Необработанное исключение: KeyError: 9
2025-08-03 16:53:21,432 - ERROR - Трассировка стека:
Traceback (most recent call last):
  File "C:\Users\Alex\Competitions_TT_v1.1\venv\Lib\site-packages\pandas\core\indexes\base.py", line 3812, in get_loc
    return self._engine.get_loc(casted_key)
           ~~~~~~~~~~~~~~~~~~~~^^^^^^^^^^^^
  File "pandas/_libs/index.pyx", line 167, in pandas._libs.index.IndexEngine.get_loc
  File "pandas/_libs/index.pyx", line 196, in pandas._libs.index.IndexEngine.get_loc
  File "pandas/_libs/hashtable_class_helper.pxi", line 2606, in pandas._libs.hashtable.Int64HashTable.get_item
  File "pandas/_libs/hashtable_class_helper.pxi", line 2630, in pandas._libs.hashtable.Int64HashTable.get_item
KeyError: 9

The above exception was the direct cause of the following exception:

Traceback (most recent call last):
  File "c:\Users\Alex\Competitions_TT_v1.1\main.py", line 167, in data
    val = str(self._data[index.row()][index.column()])
              ~~~~~~~~~~^^^^^^^^^^^^^
  File "C:\Users\Alex\Competitions_TT_v1.1\venv\Lib\site-packages\pandas\core\frame.py", line 4107, in __getitem__
    indexer = self.columns.get_loc(key)
  File "C:\Users\Alex\Competitions_TT_v1.1\venv\Lib\site-packages\pandas\core\indexes\base.py", line 3819, in get_loc
    raise KeyError(key) from err
KeyError: 9
2025-08-03 16:53:21,452 - ERROR - Необработанное исключение: KeyError: 9
2025-08-03 16:53:21,458 - ERROR - Трассировка стека:
Traceback (most recent call last):
  File "C:\Users\Alex\Competitions_TT_v1.1\venv\Lib\site-packages\pandas\core\indexes\base.py", line 3812, in get_loc
    return self._engine.get_loc(casted_key)
           ~~~~~~~~~~~~~~~~~~~~^^^^^^^^^^^^
  File "pandas/_libs/index.pyx", line 167, in pandas._libs.index.IndexEngine.get_loc
  File "pandas/_libs/index.pyx", line 196, in pandas._libs.index.IndexEngine.get_loc
  File "pandas/_libs/hashtable_class_helper.pxi", line 2606, in pandas._libs.hashtable.Int64HashTable.get_item
  File "pandas/_libs/hashtable_class_helper.pxi", line 2630, in pandas._libs.hashtable.Int64HashTable.get_item
KeyError: 9

The above exception was the direct cause of the following exception:

Traceback (most recent call last):
  File "c:\Users\Alex\Competitions_TT_v1.1\main.py", line 165, in data
    return str(self._data[index.row()][index.column()])
               ~~~~~~~~~~^^^^^^^^^^^^^
  File "C:\Users\Alex\Competitions_TT_v1.1\venv\Lib\site-packages\pandas\core\frame.py", line 4107, in __getitem__
    indexer = self.columns.get_loc(key)
  File "C:\Users\Alex\Competitions_TT_v1.1\venv\Lib\site-packages\pandas\core\indexes\base.py", line 3819, in get_loc
    raise KeyError(key) from err
KeyError: 9
2025-08-03 16:53:21,485 - ERROR - Необработанное исключение: KeyError: 9
2025-08-03 16:53:21,494 - ERROR - Трассировка стека:
Traceback (most recent call last):
  File "C:\Users\Alex\Competitions_TT_v1.1\venv\Lib\site-packages\pandas\core\indexes\base.py", line 3812, in get_loc
    return self._engine.get_loc(casted_key)
           ~~~~~~~~~~~~~~~~~~~~^^^^^^^^^^^^
  File "pandas/_libs/index.pyx", line 167, in pandas._libs.index.IndexEngine.get_loc
  File "pandas/_libs/index.pyx", line 196, in pandas._libs.index.IndexEngine.get_loc
  File "pandas/_libs/hashtable_class_helper.pxi", line 2606, in pandas._libs.hashtable.Int64HashTable.get_item
  File "pandas/_libs/hashtable_class_helper.pxi", line 2630, in pandas._libs.hashtable.Int64HashTable.get_item
KeyError: 9

The above exception was the direct cause of the following exception:

Traceback (most recent call last):
  File "c:\Users\Alex\Competitions_TT_v1.1\main.py", line 167, in data
    val = str(self._data[index.row()][index.column()])
              ~~~~~~~~~~^^^^^^^^^^^^^
  File "C:\Users\Alex\Competitions_TT_v1.1\venv\Lib\site-packages\pandas\core\frame.py", line 4107, in __getitem__
    indexer = self.columns.get_loc(key)
  File "C:\Users\Alex\Competitions_TT_v1.1\venv\Lib\site-packages\pandas\core\indexes\base.py", line 3819, in get_loc
    raise KeyError(key) from err
KeyError: 9
2025-08-03 16:53:21,540 - ERROR - Необработанное исключение: KeyError: 9
2025-08-03 16:53:21,547 - ERROR - Трассировка стека:
Traceback (most recent call last):
  File "C:\Users\Alex\Competitions_TT_v1.1\venv\Lib\site-packages\pandas\core\indexes\base.py", line 3812, in get_loc
    return self._engine.get_loc(casted_key)
           ~~~~~~~~~~~~~~~~~~~~^^^^^^^^^^^^
  File "pandas/_libs/index.pyx", line 167, in pandas._libs.index.IndexEngine.get_loc
  File "pandas/_libs/index.pyx", line 196, in pandas._libs.index.IndexEngine.get_loc
  File "pandas/_libs/hashtable_class_helper.pxi", line 2606, in pandas._libs.hashtable.Int64HashTable.get_item
  File "pandas/_libs/hashtable_class_helper.pxi", line 2630, in pandas._libs.hashtable.Int64HashTable.get_item
KeyError: 9

The above exception was the direct cause of the following exception:

Traceback (most recent call last):
  File "c:\Users\Alex\Competitions_TT_v1.1\main.py", line 165, in data
    return str(self._data[index.row()][index.column()])
               ~~~~~~~~~~^^^^^^^^^^^^^
  File "C:\Users\Alex\Competitions_TT_v1.1\venv\Lib\site-packages\pandas\core\frame.py", line 4107, in __getitem__
    indexer = self.columns.get_loc(key)
  File "C:\Users\Alex\Competitions_TT_v1.1\venv\Lib\site-packages\pandas\core\indexes\base.py", line 3819, in get_loc
    raise KeyError(key) from err
KeyError: 9
2025-08-03 16:53:21,564 - ERROR - Необработанное исключение: KeyError: 9
2025-08-03 16:53:21,565 - ERROR - Трассировка стека:
Traceback (most recent call last):
  File "C:\Users\Alex\Competitions_TT_v1.1\venv\Lib\site-packages\pandas\core\indexes\base.py", line 3812, in get_loc
    return self._engine.get_loc(casted_key)
           ~~~~~~~~~~~~~~~~~~~~^^^^^^^^^^^^
  File "pandas/_libs/index.pyx", line 167, in pandas._libs.index.IndexEngine.get_loc
  File "pandas/_libs/index.pyx", line 196, in pandas._libs.index.IndexEngine.get_loc
  File "pandas/_libs/hashtable_class_helper.pxi", line 2606, in pandas._libs.hashtable.Int64HashTable.get_item
  File "pandas/_libs/hashtable_class_helper.pxi", line 2630, in pandas._libs.hashtable.Int64HashTable.get_item
KeyError: 9

The above exception was the direct cause of the following exception:

Traceback (most recent call last):
  File "c:\Users\Alex\Competitions_TT_v1.1\main.py", line 167, in data
    val = str(self._data[index.row()][index.column()])
              ~~~~~~~~~~^^^^^^^^^^^^^
  File "C:\Users\Alex\Competitions_TT_v1.1\venv\Lib\site-packages\pandas\core\frame.py", line 4107, in __getitem__
    indexer = self.columns.get_loc(key)
  File "C:\Users\Alex\Competitions_TT_v1.1\venv\Lib\site-packages\pandas\core\indexes\base.py", line 3819, in get_loc
    raise KeyError(key) from err
KeyError: 9
2025-08-03 16:53:21,574 - ERROR - Необработанное исключение: KeyError: 9
2025-08-03 16:53:21,578 - ERROR - Трассировка стека:
Traceback (most recent call last):
  File "C:\Users\Alex\Competitions_TT_v1.1\venv\Lib\site-packages\pandas\core\indexes\base.py", line 3812, in get_loc
    return self._engine.get_loc(casted_key)
           ~~~~~~~~~~~~~~~~~~~~^^^^^^^^^^^^
  File "pandas/_libs/index.pyx", line 167, in pandas._libs.index.IndexEngine.get_loc
  File "pandas/_libs/index.pyx", line 196, in pandas._libs.index.IndexEngine.get_loc
  File "pandas/_libs/hashtable_class_helper.pxi", line 2606, in pandas._libs.hashtable.Int64HashTable.get_item
  File "pandas/_libs/hashtable_class_helper.pxi", line 2630, in pandas._libs.hashtable.Int64HashTable.get_item
KeyError: 9

The above exception was the direct cause of the following exception:

Traceback (most recent call last):
  File "c:\Users\Alex\Competitions_TT_v1.1\main.py", line 165, in data
    return str(self._data[index.row()][index.column()])
               ~~~~~~~~~~^^^^^^^^^^^^^
  File "C:\Users\Alex\Competitions_TT_v1.1\venv\Lib\site-packages\pandas\core\frame.py", line 4107, in __getitem__
    indexer = self.columns.get_loc(key)
  File "C:\Users\Alex\Competitions_TT_v1.1\venv\Lib\site-packages\pandas\core\indexes\base.py", line 3819, in get_loc
    raise KeyError(key) from err
KeyError: 9
2025-08-03 16:53:21,596 - ERROR - Необработанное исключение: KeyError: 9
2025-08-03 16:53:21,598 - ERROR - Трассировка стека:
Traceback (most recent call last):
  File "C:\Users\Alex\Competitions_TT_v1.1\venv\Lib\site-packages\pandas\core\indexes\base.py", line 3812, in get_loc
    return self._engine.get_loc(casted_key)
           ~~~~~~~~~~~~~~~~~~~~^^^^^^^^^^^^
  File "pandas/_libs/index.pyx", line 167, in pandas._libs.index.IndexEngine.get_loc
  File "pandas/_libs/index.pyx", line 196, in pandas._libs.index.IndexEngine.get_loc
  File "pandas/_libs/hashtable_class_helper.pxi", line 2606, in pandas._libs.hashtable.Int64HashTable.get_item
  File "pandas/_libs/hashtable_class_helper.pxi", line 2630, in pandas._libs.hashtable.Int64HashTable.get_item
KeyError: 9

The above exception was the direct cause of the following exception:

Traceback (most recent call last):
  File "c:\Users\Alex\Competitions_TT_v1.1\main.py", line 167, in data
    val = str(self._data[index.row()][index.column()])
              ~~~~~~~~~~^^^^^^^^^^^^^
  File "C:\Users\Alex\Competitions_TT_v1.1\venv\Lib\site-packages\pandas\core\frame.py", line 4107, in __getitem__
    indexer = self.columns.get_loc(key)
  File "C:\Users\Alex\Competitions_TT_v1.1\venv\Lib\site-packages\pandas\core\indexes\base.py", line 3819, in get_loc
    raise KeyError(key) from err
KeyError: 9
2025-08-03 16:53:21,608 - ERROR - Необработанное исключение: KeyError: 9
2025-08-03 16:53:21,611 - ERROR - Трассировка стека:
Traceback (most recent call last):
  File "C:\Users\Alex\Competitions_TT_v1.1\venv\Lib\site-packages\pandas\core\indexes\base.py", line 3812, in get_loc
    return self._engine.get_loc(casted_key)
           ~~~~~~~~~~~~~~~~~~~~^^^^^^^^^^^^
  File "pandas/_libs/index.pyx", line 167, in pandas._libs.index.IndexEngine.get_loc
  File "pandas/_libs/index.pyx", line 196, in pandas._libs.index.IndexEngine.get_loc
  File "pandas/_libs/hashtable_class_helper.pxi", line 2606, in pandas._libs.hashtable.Int64HashTable.get_item
  File "pandas/_libs/hashtable_class_helper.pxi", line 2630, in pandas._libs.hashtable.Int64HashTable.get_item
KeyError: 9

The above exception was the direct cause of the following exception:

Traceback (most recent call last):
  File "c:\Users\Alex\Competitions_TT_v1.1\main.py", line 165, in data
    return str(self._data[index.row()][index.column()])
               ~~~~~~~~~~^^^^^^^^^^^^^
  File "C:\Users\Alex\Competitions_TT_v1.1\venv\Lib\site-packages\pandas\core\frame.py", line 4107, in __getitem__
    indexer = self.columns.get_loc(key)
  File "C:\Users\Alex\Competitions_TT_v1.1\venv\Lib\site-packages\pandas\core\indexes\base.py", line 3819, in get_loc
    raise KeyError(key) from err
KeyError: 9
2025-08-03 16:53:21,635 - ERROR - Необработанное исключение: KeyError: 9
2025-08-03 16:53:21,637 - ERROR - Трассировка стека:
Traceback (most recent call last):
  File "C:\Users\Alex\Competitions_TT_v1.1\venv\Lib\site-packages\pandas\core\indexes\base.py", line 3812, in get_loc
    return self._engine.get_loc(casted_key)
           ~~~~~~~~~~~~~~~~~~~~^^^^^^^^^^^^
  File "pandas/_libs/index.pyx", line 167, in pandas._libs.index.IndexEngine.get_loc
  File "pandas/_libs/index.pyx", line 196, in pandas._libs.index.IndexEngine.get_loc
  File "pandas/_libs/hashtable_class_helper.pxi", line 2606, in pandas._libs.hashtable.Int64HashTable.get_item
  File "pandas/_libs/hashtable_class_helper.pxi", line 2630, in pandas._libs.hashtable.Int64HashTable.get_item
KeyError: 9

The above exception was the direct cause of the following exception:

Traceback (most recent call last):
  File "c:\Users\Alex\Competitions_TT_v1.1\main.py", line 167, in data
    val = str(self._data[index.row()][index.column()])
              ~~~~~~~~~~^^^^^^^^^^^^^
  File "C:\Users\Alex\Competitions_TT_v1.1\venv\Lib\site-packages\pandas\core\frame.py", line 4107, in __getitem__
    indexer = self.columns.get_loc(key)
  File "C:\Users\Alex\Competitions_TT_v1.1\venv\Lib\site-packages\pandas\core\indexes\base.py", line 3819, in get_loc
    raise KeyError(key) from err
KeyError: 9
2025-08-03 16:53:21,646 - ERROR - Необработанное исключение: KeyError: 9
2025-08-03 16:53:21,648 - ERROR - Трассировка стека:
Traceback (most recent call last):
  File "C:\Users\Alex\Competitions_TT_v1.1\venv\Lib\site-packages\pandas\core\indexes\base.py", line 3812, in get_loc
    return self._engine.get_loc(casted_key)
           ~~~~~~~~~~~~~~~~~~~~^^^^^^^^^^^^
  File "pandas/_libs/index.pyx", line 167, in pandas._libs.index.IndexEngine.get_loc
  File "pandas/_libs/index.pyx", line 196, in pandas._libs.index.IndexEngine.get_loc
  File "pandas/_libs/hashtable_class_helper.pxi", line 2606, in pandas._libs.hashtable.Int64HashTable.get_item
  File "pandas/_libs/hashtable_class_helper.pxi", line 2630, in pandas._libs.hashtable.Int64HashTable.get_item
KeyError: 9

The above exception was the direct cause of the following exception:

Traceback (most recent call last):
  File "c:\Users\Alex\Competitions_TT_v1.1\main.py", line 165, in data
    return str(self._data[index.row()][index.column()])
               ~~~~~~~~~~^^^^^^^^^^^^^
  File "C:\Users\Alex\Competitions_TT_v1.1\venv\Lib\site-packages\pandas\core\frame.py", line 4107, in __getitem__
    indexer = self.columns.get_loc(key)
  File "C:\Users\Alex\Competitions_TT_v1.1\venv\Lib\site-packages\pandas\core\indexes\base.py", line 3819, in get_loc
    raise KeyError(key) from err
KeyError: 9
2025-08-03 16:53:21,687 - ERROR - Необработанное исключение: KeyError: 9
2025-08-03 16:53:21,696 - ERROR - Трассировка стека:
Traceback (most recent call last):
  File "C:\Users\Alex\Competitions_TT_v1.1\venv\Lib\site-packages\pandas\core\indexes\base.py", line 3812, in get_loc
    return self._engine.get_loc(casted_key)
           ~~~~~~~~~~~~~~~~~~~~^^^^^^^^^^^^
  File "pandas/_libs/index.pyx", line 167, in pandas._libs.index.IndexEngine.get_loc
  File "pandas/_libs/index.pyx", line 196, in pandas._libs.index.IndexEngine.get_loc
  File "pandas/_libs/hashtable_class_helper.pxi", line 2606, in pandas._libs.hashtable.Int64HashTable.get_item
  File "pandas/_libs/hashtable_class_helper.pxi", line 2630, in pandas._libs.hashtable.Int64HashTable.get_item
KeyError: 9

The above exception was the direct cause of the following exception:

Traceback (most recent call last):
  File "c:\Users\Alex\Competitions_TT_v1.1\main.py", line 167, in data
    val = str(self._data[index.row()][index.column()])
              ~~~~~~~~~~^^^^^^^^^^^^^
  File "C:\Users\Alex\Competitions_TT_v1.1\venv\Lib\site-packages\pandas\core\frame.py", line 4107, in __getitem__
    indexer = self.columns.get_loc(key)
  File "C:\Users\Alex\Competitions_TT_v1.1\venv\Lib\site-packages\pandas\core\indexes\base.py", line 3819, in get_loc
    raise KeyError(key) from err
KeyError: 9
2025-08-03 16:53:21,710 - ERROR - Необработанное исключение: KeyError: 9
2025-08-03 16:53:21,711 - ERROR - Трассировка стека:
Traceback (most recent call last):
  File "C:\Users\Alex\Competitions_TT_v1.1\venv\Lib\site-packages\pandas\core\indexes\base.py", line 3812, in get_loc
    return self._engine.get_loc(casted_key)
           ~~~~~~~~~~~~~~~~~~~~^^^^^^^^^^^^
  File "pandas/_libs/index.pyx", line 167, in pandas._libs.index.IndexEngine.get_loc
  File "pandas/_libs/index.pyx", line 196, in pandas._libs.index.IndexEngine.get_loc
  File "pandas/_libs/hashtable_class_helper.pxi", line 2606, in pandas._libs.hashtable.Int64HashTable.get_item
  File "pandas/_libs/hashtable_class_helper.pxi", line 2630, in pandas._libs.hashtable.Int64HashTable.get_item
KeyError: 9

The above exception was the direct cause of the following exception:

Traceback (most recent call last):
  File "c:\Users\Alex\Competitions_TT_v1.1\main.py", line 165, in data
    return str(self._data[index.row()][index.column()])
               ~~~~~~~~~~^^^^^^^^^^^^^
  File "C:\Users\Alex\Competitions_TT_v1.1\venv\Lib\site-packages\pandas\core\frame.py", line 4107, in __getitem__
    indexer = self.columns.get_loc(key)
  File "C:\Users\Alex\Competitions_TT_v1.1\venv\Lib\site-packages\pandas\core\indexes\base.py", line 3819, in get_loc
    raise KeyError(key) from err
KeyError: 9
2025-08-03 16:53:21,735 - ERROR - Необработанное исключение: KeyError: 9
2025-08-03 16:53:21,737 - ERROR - Трассировка стека:
Traceback (most recent call last):
  File "C:\Users\Alex\Competitions_TT_v1.1\venv\Lib\site-packages\pandas\core\indexes\base.py", line 3812, in get_loc
    return self._engine.get_loc(casted_key)
           ~~~~~~~~~~~~~~~~~~~~^^^^^^^^^^^^
  File "pandas/_libs/index.pyx", line 167, in pandas._libs.index.IndexEngine.get_loc
  File "pandas/_libs/index.pyx", line 196, in pandas._libs.index.IndexEngine.get_loc
  File "pandas/_libs/hashtable_class_helper.pxi", line 2606, in pandas._libs.hashtable.Int64HashTable.get_item
  File "pandas/_libs/hashtable_class_helper.pxi", line 2630, in pandas._libs.hashtable.Int64HashTable.get_item
KeyError: 9

The above exception was the direct cause of the following exception:

Traceback (most recent call last):
  File "c:\Users\Alex\Competitions_TT_v1.1\main.py", line 167, in data
    val = str(self._data[index.row()][index.column()])
              ~~~~~~~~~~^^^^^^^^^^^^^
  File "C:\Users\Alex\Competitions_TT_v1.1\venv\Lib\site-packages\pandas\core\frame.py", line 4107, in __getitem__
    indexer = self.columns.get_loc(key)
  File "C:\Users\Alex\Competitions_TT_v1.1\venv\Lib\site-packages\pandas\core\indexes\base.py", line 3819, in get_loc
    raise KeyError(key) from err
KeyError: 9
2025-08-03 16:53:21,741 - ERROR - Необработанное исключение: KeyError: 9
2025-08-03 16:53:21,741 - ERROR - Трассировка стека:
Traceback (most recent call last):
  File "C:\Users\Alex\Competitions_TT_v1.1\venv\Lib\site-packages\pandas\core\indexes\base.py", line 3812, in get_loc
    return self._engine.get_loc(casted_key)
           ~~~~~~~~~~~~~~~~~~~~^^^^^^^^^^^^
  File "pandas/_libs/index.pyx", line 167, in pandas._libs.index.IndexEngine.get_loc
  File "pandas/_libs/index.pyx", line 196, in pandas._libs.index.IndexEngine.get_loc
  File "pandas/_libs/hashtable_class_helper.pxi", line 2606, in pandas._libs.hashtable.Int64HashTable.get_item
  File "pandas/_libs/hashtable_class_helper.pxi", line 2630, in pandas._libs.hashtable.Int64HashTable.get_item
KeyError: 9

The above exception was the direct cause of the following exception:

Traceback (most recent call last):
  File "c:\Users\Alex\Competitions_TT_v1.1\main.py", line 165, in data
    return str(self._data[index.row()][index.column()])
               ~~~~~~~~~~^^^^^^^^^^^^^
  File "C:\Users\Alex\Competitions_TT_v1.1\venv\Lib\site-packages\pandas\core\frame.py", line 4107, in __getitem__
    indexer = self.columns.get_loc(key)
  File "C:\Users\Alex\Competitions_TT_v1.1\venv\Lib\site-packages\pandas\core\indexes\base.py", line 3819, in get_loc
    raise KeyError(key) from err
KeyError: 9
2025-08-03 16:53:21,746 - ERROR - Необработанное исключение: KeyError: 9
2025-08-03 16:53:21,746 - ERROR - Трассировка стека:
Traceback (most recent call last):
  File "C:\Users\Alex\Competitions_TT_v1.1\venv\Lib\site-packages\pandas\core\indexes\base.py", line 3812, in get_loc
    return self._engine.get_loc(casted_key)
           ~~~~~~~~~~~~~~~~~~~~^^^^^^^^^^^^
  File "pandas/_libs/index.pyx", line 167, in pandas._libs.index.IndexEngine.get_loc
  File "pandas/_libs/index.pyx", line 196, in pandas._libs.index.IndexEngine.get_loc
  File "pandas/_libs/hashtable_class_helper.pxi", line 2606, in pandas._libs.hashtable.Int64HashTable.get_item
  File "pandas/_libs/hashtable_class_helper.pxi", line 2630, in pandas._libs.hashtable.Int64HashTable.get_item
KeyError: 9

The above exception was the direct cause of the following exception:

Traceback (most recent call last):
  File "c:\Users\Alex\Competitions_TT_v1.1\main.py", line 167, in data
    val = str(self._data[index.row()][index.column()])
              ~~~~~~~~~~^^^^^^^^^^^^^
  File "C:\Users\Alex\Competitions_TT_v1.1\venv\Lib\site-packages\pandas\core\frame.py", line 4107, in __getitem__
    indexer = self.columns.get_loc(key)
  File "C:\Users\Alex\Competitions_TT_v1.1\venv\Lib\site-packages\pandas\core\indexes\base.py", line 3819, in get_loc
    raise KeyError(key) from err
KeyError: 9
2025-08-03 16:53:21,756 - ERROR - Необработанное исключение: KeyError: 9
2025-08-03 16:53:21,756 - ERROR - Трассировка стека:
Traceback (most recent call last):
  File "C:\Users\Alex\Competitions_TT_v1.1\venv\Lib\site-packages\pandas\core\indexes\base.py", line 3812, in get_loc
    return self._engine.get_loc(casted_key)
           ~~~~~~~~~~~~~~~~~~~~^^^^^^^^^^^^
  File "pandas/_libs/index.pyx", line 167, in pandas._libs.index.IndexEngine.get_loc
  File "pandas/_libs/index.pyx", line 196, in pandas._libs.index.IndexEngine.get_loc
  File "pandas/_libs/hashtable_class_helper.pxi", line 2606, in pandas._libs.hashtable.Int64HashTable.get_item
  File "pandas/_libs/hashtable_class_helper.pxi", line 2630, in pandas._libs.hashtable.Int64HashTable.get_item
KeyError: 9

The above exception was the direct cause of the following exception:

Traceback (most recent call last):
  File "c:\Users\Alex\Competitions_TT_v1.1\main.py", line 165, in data
    return str(self._data[index.row()][index.column()])
               ~~~~~~~~~~^^^^^^^^^^^^^
  File "C:\Users\Alex\Competitions_TT_v1.1\venv\Lib\site-packages\pandas\core\frame.py", line 4107, in __getitem__
    indexer = self.columns.get_loc(key)
  File "C:\Users\Alex\Competitions_TT_v1.1\venv\Lib\site-packages\pandas\core\indexes\base.py", line 3819, in get_loc
    raise KeyError(key) from err
KeyError: 9
2025-08-03 16:57:00,865 - ERROR - Необработанное исключение: KeyError: 9
2025-08-03 16:57:00,866 - ERROR - Трассировка стека:
Traceback (most recent call last):
  File "C:\Users\Alex\Competitions_TT_v1.1\venv\Lib\site-packages\pandas\core\indexes\base.py", line 3812, in get_loc
    return self._engine.get_loc(casted_key)
           ~~~~~~~~~~~~~~~~~~~~^^^^^^^^^^^^
  File "pandas/_libs/index.pyx", line 167, in pandas._libs.index.IndexEngine.get_loc
  File "pandas/_libs/index.pyx", line 196, in pandas._libs.index.IndexEngine.get_loc
  File "pandas/_libs/hashtable_class_helper.pxi", line 2606, in pandas._libs.hashtable.Int64HashTable.get_item
  File "pandas/_libs/hashtable_class_helper.pxi", line 2630, in pandas._libs.hashtable.Int64HashTable.get_item
KeyError: 9

The above exception was the direct cause of the following exception:

Traceback (most recent call last):
  File "c:\Users\Alex\Competitions_TT_v1.1\main.py", line 167, in data
    val = str(self._data[index.row()][index.column()])
              ~~~~~~~~~~^^^^^^^^^^^^^
  File "C:\Users\Alex\Competitions_TT_v1.1\venv\Lib\site-packages\pandas\core\frame.py", line 4107, in __getitem__
    indexer = self.columns.get_loc(key)
  File "C:\Users\Alex\Competitions_TT_v1.1\venv\Lib\site-packages\pandas\core\indexes\base.py", line 3819, in get_loc
    raise KeyError(key) from err
KeyError: 9
2025-08-03 16:57:00,958 - ERROR - Необработанное исключение: KeyError: 9
2025-08-03 16:57:00,958 - ERROR - Трассировка стека:
Traceback (most recent call last):
  File "C:\Users\Alex\Competitions_TT_v1.1\venv\Lib\site-packages\pandas\core\indexes\base.py", line 3812, in get_loc
    return self._engine.get_loc(casted_key)
           ~~~~~~~~~~~~~~~~~~~~^^^^^^^^^^^^
  File "pandas/_libs/index.pyx", line 167, in pandas._libs.index.IndexEngine.get_loc
  File "pandas/_libs/index.pyx", line 196, in pandas._libs.index.IndexEngine.get_loc
  File "pandas/_libs/hashtable_class_helper.pxi", line 2606, in pandas._libs.hashtable.Int64HashTable.get_item
  File "pandas/_libs/hashtable_class_helper.pxi", line 2630, in pandas._libs.hashtable.Int64HashTable.get_item
KeyError: 9

The above exception was the direct cause of the following exception:

Traceback (most recent call last):
  File "c:\Users\Alex\Competitions_TT_v1.1\main.py", line 165, in data
    return str(self._data[index.row()][index.column()])
               ~~~~~~~~~~^^^^^^^^^^^^^
  File "C:\Users\Alex\Competitions_TT_v1.1\venv\Lib\site-packages\pandas\core\frame.py", line 4107, in __getitem__
    indexer = self.columns.get_loc(key)
  File "C:\Users\Alex\Competitions_TT_v1.1\venv\Lib\site-packages\pandas\core\indexes\base.py", line 3819, in get_loc
    raise KeyError(key) from err
KeyError: 9
2025-08-03 16:57:00,962 - ERROR - Необработанное исключение: KeyError: 9
2025-08-03 16:57:00,962 - ERROR - Трассировка стека:
Traceback (most recent call last):
  File "C:\Users\Alex\Competitions_TT_v1.1\venv\Lib\site-packages\pandas\core\indexes\base.py", line 3812, in get_loc
    return self._engine.get_loc(casted_key)
           ~~~~~~~~~~~~~~~~~~~~^^^^^^^^^^^^
  File "pandas/_libs/index.pyx", line 167, in pandas._libs.index.IndexEngine.get_loc
  File "pandas/_libs/index.pyx", line 196, in pandas._libs.index.IndexEngine.get_loc
  File "pandas/_libs/hashtable_class_helper.pxi", line 2606, in pandas._libs.hashtable.Int64HashTable.get_item
  File "pandas/_libs/hashtable_class_helper.pxi", line 2630, in pandas._libs.hashtable.Int64HashTable.get_item
KeyError: 9

The above exception was the direct cause of the following exception:

Traceback (most recent call last):
  File "c:\Users\Alex\Competitions_TT_v1.1\main.py", line 167, in data
    val = str(self._data[index.row()][index.column()])
              ~~~~~~~~~~^^^^^^^^^^^^^
  File "C:\Users\Alex\Competitions_TT_v1.1\venv\Lib\site-packages\pandas\core\frame.py", line 4107, in __getitem__
    indexer = self.columns.get_loc(key)
  File "C:\Users\Alex\Competitions_TT_v1.1\venv\Lib\site-packages\pandas\core\indexes\base.py", line 3819, in get_loc
    raise KeyError(key) from err
KeyError: 9
2025-08-03 16:57:00,971 - ERROR - Необработанное исключение: KeyError: 9
2025-08-03 16:57:00,971 - ERROR - Трассировка стека:
Traceback (most recent call last):
  File "C:\Users\Alex\Competitions_TT_v1.1\venv\Lib\site-packages\pandas\core\indexes\base.py", line 3812, in get_loc
    return self._engine.get_loc(casted_key)
           ~~~~~~~~~~~~~~~~~~~~^^^^^^^^^^^^
  File "pandas/_libs/index.pyx", line 167, in pandas._libs.index.IndexEngine.get_loc
  File "pandas/_libs/index.pyx", line 196, in pandas._libs.index.IndexEngine.get_loc
  File "pandas/_libs/hashtable_class_helper.pxi", line 2606, in pandas._libs.hashtable.Int64HashTable.get_item
  File "pandas/_libs/hashtable_class_helper.pxi", line 2630, in pandas._libs.hashtable.Int64HashTable.get_item
KeyError: 9

The above exception was the direct cause of the following exception:

Traceback (most recent call last):
  File "c:\Users\Alex\Competitions_TT_v1.1\main.py", line 165, in data
    return str(self._data[index.row()][index.column()])
               ~~~~~~~~~~^^^^^^^^^^^^^
  File "C:\Users\Alex\Competitions_TT_v1.1\venv\Lib\site-packages\pandas\core\frame.py", line 4107, in __getitem__
    indexer = self.columns.get_loc(key)
  File "C:\Users\Alex\Competitions_TT_v1.1\venv\Lib\site-packages\pandas\core\indexes\base.py", line 3819, in get_loc
    raise KeyError(key) from err
KeyError: 9
2025-08-03 16:57:00,975 - ERROR - Необработанное исключение: KeyError: 9
2025-08-03 16:57:00,975 - ERROR - Трассировка стека:
Traceback (most recent call last):
  File "C:\Users\Alex\Competitions_TT_v1.1\venv\Lib\site-packages\pandas\core\indexes\base.py", line 3812, in get_loc
    return self._engine.get_loc(casted_key)
           ~~~~~~~~~~~~~~~~~~~~^^^^^^^^^^^^
  File "pandas/_libs/index.pyx", line 167, in pandas._libs.index.IndexEngine.get_loc
  File "pandas/_libs/index.pyx", line 196, in pandas._libs.index.IndexEngine.get_loc
  File "pandas/_libs/hashtable_class_helper.pxi", line 2606, in pandas._libs.hashtable.Int64HashTable.get_item
  File "pandas/_libs/hashtable_class_helper.pxi", line 2630, in pandas._libs.hashtable.Int64HashTable.get_item
KeyError: 9

The above exception was the direct cause of the following exception:

Traceback (most recent call last):
  File "c:\Users\Alex\Competitions_TT_v1.1\main.py", line 167, in data
    val = str(self._data[index.row()][index.column()])
              ~~~~~~~~~~^^^^^^^^^^^^^
  File "C:\Users\Alex\Competitions_TT_v1.1\venv\Lib\site-packages\pandas\core\frame.py", line 4107, in __getitem__
    indexer = self.columns.get_loc(key)
  File "C:\Users\Alex\Competitions_TT_v1.1\venv\Lib\site-packages\pandas\core\indexes\base.py", line 3819, in get_loc
    raise KeyError(key) from err
KeyError: 9
2025-08-03 16:57:00,979 - ERROR - Необработанное исключение: KeyError: 9
2025-08-03 16:57:00,983 - ERROR - Трассировка стека:
Traceback (most recent call last):
  File "C:\Users\Alex\Competitions_TT_v1.1\venv\Lib\site-packages\pandas\core\indexes\base.py", line 3812, in get_loc
    return self._engine.get_loc(casted_key)
           ~~~~~~~~~~~~~~~~~~~~^^^^^^^^^^^^
  File "pandas/_libs/index.pyx", line 167, in pandas._libs.index.IndexEngine.get_loc
  File "pandas/_libs/index.pyx", line 196, in pandas._libs.index.IndexEngine.get_loc
  File "pandas/_libs/hashtable_class_helper.pxi", line 2606, in pandas._libs.hashtable.Int64HashTable.get_item
  File "pandas/_libs/hashtable_class_helper.pxi", line 2630, in pandas._libs.hashtable.Int64HashTable.get_item
KeyError: 9

The above exception was the direct cause of the following exception:

Traceback (most recent call last):
  File "c:\Users\Alex\Competitions_TT_v1.1\main.py", line 165, in data
    return str(self._data[index.row()][index.column()])
               ~~~~~~~~~~^^^^^^^^^^^^^
  File "C:\Users\Alex\Competitions_TT_v1.1\venv\Lib\site-packages\pandas\core\frame.py", line 4107, in __getitem__
    indexer = self.columns.get_loc(key)
  File "C:\Users\Alex\Competitions_TT_v1.1\venv\Lib\site-packages\pandas\core\indexes\base.py", line 3819, in get_loc
    raise KeyError(key) from err
KeyError: 9
2025-08-03 16:57:00,988 - ERROR - Необработанное исключение: KeyError: 9
2025-08-03 16:57:00,988 - ERROR - Трассировка стека:
Traceback (most recent call last):
  File "C:\Users\Alex\Competitions_TT_v1.1\venv\Lib\site-packages\pandas\core\indexes\base.py", line 3812, in get_loc
    return self._engine.get_loc(casted_key)
           ~~~~~~~~~~~~~~~~~~~~^^^^^^^^^^^^
  File "pandas/_libs/index.pyx", line 167, in pandas._libs.index.IndexEngine.get_loc
  File "pandas/_libs/index.pyx", line 196, in pandas._libs.index.IndexEngine.get_loc
  File "pandas/_libs/hashtable_class_helper.pxi", line 2606, in pandas._libs.hashtable.Int64HashTable.get_item
  File "pandas/_libs/hashtable_class_helper.pxi", line 2630, in pandas._libs.hashtable.Int64HashTable.get_item
KeyError: 9

The above exception was the direct cause of the following exception:

Traceback (most recent call last):
  File "c:\Users\Alex\Competitions_TT_v1.1\main.py", line 167, in data
    val = str(self._data[index.row()][index.column()])
              ~~~~~~~~~~^^^^^^^^^^^^^
  File "C:\Users\Alex\Competitions_TT_v1.1\venv\Lib\site-packages\pandas\core\frame.py", line 4107, in __getitem__
    indexer = self.columns.get_loc(key)
  File "C:\Users\Alex\Competitions_TT_v1.1\venv\Lib\site-packages\pandas\core\indexes\base.py", line 3819, in get_loc
    raise KeyError(key) from err
KeyError: 9
2025-08-03 16:57:00,992 - ERROR - Необработанное исключение: KeyError: 9
2025-08-03 16:57:00,992 - ERROR - Трассировка стека:
Traceback (most recent call last):
  File "C:\Users\Alex\Competitions_TT_v1.1\venv\Lib\site-packages\pandas\core\indexes\base.py", line 3812, in get_loc
    return self._engine.get_loc(casted_key)
           ~~~~~~~~~~~~~~~~~~~~^^^^^^^^^^^^
  File "pandas/_libs/index.pyx", line 167, in pandas._libs.index.IndexEngine.get_loc
  File "pandas/_libs/index.pyx", line 196, in pandas._libs.index.IndexEngine.get_loc
  File "pandas/_libs/hashtable_class_helper.pxi", line 2606, in pandas._libs.hashtable.Int64HashTable.get_item
  File "pandas/_libs/hashtable_class_helper.pxi", line 2630, in pandas._libs.hashtable.Int64HashTable.get_item
KeyError: 9

The above exception was the direct cause of the following exception:

Traceback (most recent call last):
  File "c:\Users\Alex\Competitions_TT_v1.1\main.py", line 165, in data
    return str(self._data[index.row()][index.column()])
               ~~~~~~~~~~^^^^^^^^^^^^^
  File "C:\Users\Alex\Competitions_TT_v1.1\venv\Lib\site-packages\pandas\core\frame.py", line 4107, in __getitem__
    indexer = self.columns.get_loc(key)
  File "C:\Users\Alex\Competitions_TT_v1.1\venv\Lib\site-packages\pandas\core\indexes\base.py", line 3819, in get_loc
    raise KeyError(key) from err
KeyError: 9
2025-08-03 16:57:01,003 - ERROR - Необработанное исключение: KeyError: 9
2025-08-03 16:57:01,003 - ERROR - Трассировка стека:
Traceback (most recent call last):
  File "C:\Users\Alex\Competitions_TT_v1.1\venv\Lib\site-packages\pandas\core\indexes\base.py", line 3812, in get_loc
    return self._engine.get_loc(casted_key)
           ~~~~~~~~~~~~~~~~~~~~^^^^^^^^^^^^
  File "pandas/_libs/index.pyx", line 167, in pandas._libs.index.IndexEngine.get_loc
  File "pandas/_libs/index.pyx", line 196, in pandas._libs.index.IndexEngine.get_loc
  File "pandas/_libs/hashtable_class_helper.pxi", line 2606, in pandas._libs.hashtable.Int64HashTable.get_item
  File "pandas/_libs/hashtable_class_helper.pxi", line 2630, in pandas._libs.hashtable.Int64HashTable.get_item
KeyError: 9

The above exception was the direct cause of the following exception:

Traceback (most recent call last):
  File "c:\Users\Alex\Competitions_TT_v1.1\main.py", line 167, in data
    val = str(self._data[index.row()][index.column()])
              ~~~~~~~~~~^^^^^^^^^^^^^
  File "C:\Users\Alex\Competitions_TT_v1.1\venv\Lib\site-packages\pandas\core\frame.py", line 4107, in __getitem__
    indexer = self.columns.get_loc(key)
  File "C:\Users\Alex\Competitions_TT_v1.1\venv\Lib\site-packages\pandas\core\indexes\base.py", line 3819, in get_loc
    raise KeyError(key) from err
KeyError: 9
2025-08-03 16:57:01,008 - ERROR - Необработанное исключение: KeyError: 9
2025-08-03 16:57:01,009 - ERROR - Трассировка стека:
Traceback (most recent call last):
  File "C:\Users\Alex\Competitions_TT_v1.1\venv\Lib\site-packages\pandas\core\indexes\base.py", line 3812, in get_loc
    return self._engine.get_loc(casted_key)
           ~~~~~~~~~~~~~~~~~~~~^^^^^^^^^^^^
  File "pandas/_libs/index.pyx", line 167, in pandas._libs.index.IndexEngine.get_loc
  File "pandas/_libs/index.pyx", line 196, in pandas._libs.index.IndexEngine.get_loc
  File "pandas/_libs/hashtable_class_helper.pxi", line 2606, in pandas._libs.hashtable.Int64HashTable.get_item
  File "pandas/_libs/hashtable_class_helper.pxi", line 2630, in pandas._libs.hashtable.Int64HashTable.get_item
KeyError: 9

The above exception was the direct cause of the following exception:

Traceback (most recent call last):
  File "c:\Users\Alex\Competitions_TT_v1.1\main.py", line 165, in data
    return str(self._data[index.row()][index.column()])
               ~~~~~~~~~~^^^^^^^^^^^^^
  File "C:\Users\Alex\Competitions_TT_v1.1\venv\Lib\site-packages\pandas\core\frame.py", line 4107, in __getitem__
    indexer = self.columns.get_loc(key)
  File "C:\Users\Alex\Competitions_TT_v1.1\venv\Lib\site-packages\pandas\core\indexes\base.py", line 3819, in get_loc
    raise KeyError(key) from err
KeyError: 9
2025-08-03 16:57:01,013 - ERROR - Необработанное исключение: KeyError: 9
2025-08-03 16:57:01,018 - ERROR - Трассировка стека:
Traceback (most recent call last):
  File "C:\Users\Alex\Competitions_TT_v1.1\venv\Lib\site-packages\pandas\core\indexes\base.py", line 3812, in get_loc
    return self._engine.get_loc(casted_key)
           ~~~~~~~~~~~~~~~~~~~~^^^^^^^^^^^^
  File "pandas/_libs/index.pyx", line 167, in pandas._libs.index.IndexEngine.get_loc
  File "pandas/_libs/index.pyx", line 196, in pandas._libs.index.IndexEngine.get_loc
  File "pandas/_libs/hashtable_class_helper.pxi", line 2606, in pandas._libs.hashtable.Int64HashTable.get_item
  File "pandas/_libs/hashtable_class_helper.pxi", line 2630, in pandas._libs.hashtable.Int64HashTable.get_item
KeyError: 9

The above exception was the direct cause of the following exception:

Traceback (most recent call last):
  File "c:\Users\Alex\Competitions_TT_v1.1\main.py", line 167, in data
    val = str(self._data[index.row()][index.column()])
              ~~~~~~~~~~^^^^^^^^^^^^^
  File "C:\Users\Alex\Competitions_TT_v1.1\venv\Lib\site-packages\pandas\core\frame.py", line 4107, in __getitem__
    indexer = self.columns.get_loc(key)
  File "C:\Users\Alex\Competitions_TT_v1.1\venv\Lib\site-packages\pandas\core\indexes\base.py", line 3819, in get_loc
    raise KeyError(key) from err
KeyError: 9
2025-08-03 16:57:01,022 - ERROR - Необработанное исключение: KeyError: 9
2025-08-03 16:57:01,023 - ERROR - Трассировка стека:
Traceback (most recent call last):
  File "C:\Users\Alex\Competitions_TT_v1.1\venv\Lib\site-packages\pandas\core\indexes\base.py", line 3812, in get_loc
    return self._engine.get_loc(casted_key)
           ~~~~~~~~~~~~~~~~~~~~^^^^^^^^^^^^
  File "pandas/_libs/index.pyx", line 167, in pandas._libs.index.IndexEngine.get_loc
  File "pandas/_libs/index.pyx", line 196, in pandas._libs.index.IndexEngine.get_loc
  File "pandas/_libs/hashtable_class_helper.pxi", line 2606, in pandas._libs.hashtable.Int64HashTable.get_item
  File "pandas/_libs/hashtable_class_helper.pxi", line 2630, in pandas._libs.hashtable.Int64HashTable.get_item
KeyError: 9

The above exception was the direct cause of the following exception:

Traceback (most recent call last):
  File "c:\Users\Alex\Competitions_TT_v1.1\main.py", line 165, in data
    return str(self._data[index.row()][index.column()])
               ~~~~~~~~~~^^^^^^^^^^^^^
  File "C:\Users\Alex\Competitions_TT_v1.1\venv\Lib\site-packages\pandas\core\frame.py", line 4107, in __getitem__
    indexer = self.columns.get_loc(key)
  File "C:\Users\Alex\Competitions_TT_v1.1\venv\Lib\site-packages\pandas\core\indexes\base.py", line 3819, in get_loc
    raise KeyError(key) from err
KeyError: 9
2025-08-03 16:57:01,027 - ERROR - Необработанное исключение: KeyError: 9
2025-08-03 16:57:01,027 - ERROR - Трассировка стека:
Traceback (most recent call last):
  File "C:\Users\Alex\Competitions_TT_v1.1\venv\Lib\site-packages\pandas\core\indexes\base.py", line 3812, in get_loc
    return self._engine.get_loc(casted_key)
           ~~~~~~~~~~~~~~~~~~~~^^^^^^^^^^^^
  File "pandas/_libs/index.pyx", line 167, in pandas._libs.index.IndexEngine.get_loc
  File "pandas/_libs/index.pyx", line 196, in pandas._libs.index.IndexEngine.get_loc
  File "pandas/_libs/hashtable_class_helper.pxi", line 2606, in pandas._libs.hashtable.Int64HashTable.get_item
  File "pandas/_libs/hashtable_class_helper.pxi", line 2630, in pandas._libs.hashtable.Int64HashTable.get_item
KeyError: 9

The above exception was the direct cause of the following exception:

Traceback (most recent call last):
  File "c:\Users\Alex\Competitions_TT_v1.1\main.py", line 167, in data
    val = str(self._data[index.row()][index.column()])
              ~~~~~~~~~~^^^^^^^^^^^^^
  File "C:\Users\Alex\Competitions_TT_v1.1\venv\Lib\site-packages\pandas\core\frame.py", line 4107, in __getitem__
    indexer = self.columns.get_loc(key)
  File "C:\Users\Alex\Competitions_TT_v1.1\venv\Lib\site-packages\pandas\core\indexes\base.py", line 3819, in get_loc
    raise KeyError(key) from err
KeyError: 9
2025-08-03 16:57:01,036 - ERROR - Необработанное исключение: KeyError: 9
2025-08-03 16:57:01,037 - ERROR - Трассировка стека:
Traceback (most recent call last):
  File "C:\Users\Alex\Competitions_TT_v1.1\venv\Lib\site-packages\pandas\core\indexes\base.py", line 3812, in get_loc
    return self._engine.get_loc(casted_key)
           ~~~~~~~~~~~~~~~~~~~~^^^^^^^^^^^^
  File "pandas/_libs/index.pyx", line 167, in pandas._libs.index.IndexEngine.get_loc
  File "pandas/_libs/index.pyx", line 196, in pandas._libs.index.IndexEngine.get_loc
  File "pandas/_libs/hashtable_class_helper.pxi", line 2606, in pandas._libs.hashtable.Int64HashTable.get_item
  File "pandas/_libs/hashtable_class_helper.pxi", line 2630, in pandas._libs.hashtable.Int64HashTable.get_item
KeyError: 9

The above exception was the direct cause of the following exception:

Traceback (most recent call last):
  File "c:\Users\Alex\Competitions_TT_v1.1\main.py", line 165, in data
    return str(self._data[index.row()][index.column()])
               ~~~~~~~~~~^^^^^^^^^^^^^
  File "C:\Users\Alex\Competitions_TT_v1.1\venv\Lib\site-packages\pandas\core\frame.py", line 4107, in __getitem__
    indexer = self.columns.get_loc(key)
  File "C:\Users\Alex\Competitions_TT_v1.1\venv\Lib\site-packages\pandas\core\indexes\base.py", line 3819, in get_loc
    raise KeyError(key) from err
KeyError: 9
2025-08-03 16:57:01,040 - ERROR - Необработанное исключение: KeyError: 9
2025-08-03 16:57:01,041 - ERROR - Трассировка стека:
Traceback (most recent call last):
  File "C:\Users\Alex\Competitions_TT_v1.1\venv\Lib\site-packages\pandas\core\indexes\base.py", line 3812, in get_loc
    return self._engine.get_loc(casted_key)
           ~~~~~~~~~~~~~~~~~~~~^^^^^^^^^^^^
  File "pandas/_libs/index.pyx", line 167, in pandas._libs.index.IndexEngine.get_loc
  File "pandas/_libs/index.pyx", line 196, in pandas._libs.index.IndexEngine.get_loc
  File "pandas/_libs/hashtable_class_helper.pxi", line 2606, in pandas._libs.hashtable.Int64HashTable.get_item
  File "pandas/_libs/hashtable_class_helper.pxi", line 2630, in pandas._libs.hashtable.Int64HashTable.get_item
KeyError: 9

The above exception was the direct cause of the following exception:

Traceback (most recent call last):
  File "c:\Users\Alex\Competitions_TT_v1.1\main.py", line 167, in data
    val = str(self._data[index.row()][index.column()])
              ~~~~~~~~~~^^^^^^^^^^^^^
  File "C:\Users\Alex\Competitions_TT_v1.1\venv\Lib\site-packages\pandas\core\frame.py", line 4107, in __getitem__
    indexer = self.columns.get_loc(key)
  File "C:\Users\Alex\Competitions_TT_v1.1\venv\Lib\site-packages\pandas\core\indexes\base.py", line 3819, in get_loc
    raise KeyError(key) from err
KeyError: 9
2025-08-03 16:57:01,045 - ERROR - Необработанное исключение: KeyError: 9
2025-08-03 16:57:01,046 - ERROR - Трассировка стека:
Traceback (most recent call last):
  File "C:\Users\Alex\Competitions_TT_v1.1\venv\Lib\site-packages\pandas\core\indexes\base.py", line 3812, in get_loc
    return self._engine.get_loc(casted_key)
           ~~~~~~~~~~~~~~~~~~~~^^^^^^^^^^^^
  File "pandas/_libs/index.pyx", line 167, in pandas._libs.index.IndexEngine.get_loc
  File "pandas/_libs/index.pyx", line 196, in pandas._libs.index.IndexEngine.get_loc
  File "pandas/_libs/hashtable_class_helper.pxi", line 2606, in pandas._libs.hashtable.Int64HashTable.get_item
  File "pandas/_libs/hashtable_class_helper.pxi", line 2630, in pandas._libs.hashtable.Int64HashTable.get_item
KeyError: 9

The above exception was the direct cause of the following exception:

Traceback (most recent call last):
  File "c:\Users\Alex\Competitions_TT_v1.1\main.py", line 165, in data
    return str(self._data[index.row()][index.column()])
               ~~~~~~~~~~^^^^^^^^^^^^^
  File "C:\Users\Alex\Competitions_TT_v1.1\venv\Lib\site-packages\pandas\core\frame.py", line 4107, in __getitem__
    indexer = self.columns.get_loc(key)
  File "C:\Users\Alex\Competitions_TT_v1.1\venv\Lib\site-packages\pandas\core\indexes\base.py", line 3819, in get_loc
    raise KeyError(key) from err
KeyError: 9
2025-08-03 16:57:03,289 - ERROR - Необработанное исключение: KeyError: 9
2025-08-03 16:57:03,289 - ERROR - Трассировка стека:
Traceback (most recent call last):
  File "C:\Users\Alex\Competitions_TT_v1.1\venv\Lib\site-packages\pandas\core\indexes\base.py", line 3812, in get_loc
    return self._engine.get_loc(casted_key)
           ~~~~~~~~~~~~~~~~~~~~^^^^^^^^^^^^
  File "pandas/_libs/index.pyx", line 167, in pandas._libs.index.IndexEngine.get_loc
  File "pandas/_libs/index.pyx", line 196, in pandas._libs.index.IndexEngine.get_loc
  File "pandas/_libs/hashtable_class_helper.pxi", line 2606, in pandas._libs.hashtable.Int64HashTable.get_item
  File "pandas/_libs/hashtable_class_helper.pxi", line 2630, in pandas._libs.hashtable.Int64HashTable.get_item
KeyError: 9

The above exception was the direct cause of the following exception:

Traceback (most recent call last):
  File "c:\Users\Alex\Competitions_TT_v1.1\main.py", line 167, in data
    val = str(self._data[index.row()][index.column()])
              ~~~~~~~~~~^^^^^^^^^^^^^
  File "C:\Users\Alex\Competitions_TT_v1.1\venv\Lib\site-packages\pandas\core\frame.py", line 4107, in __getitem__
    indexer = self.columns.get_loc(key)
  File "C:\Users\Alex\Competitions_TT_v1.1\venv\Lib\site-packages\pandas\core\indexes\base.py", line 3819, in get_loc
    raise KeyError(key) from err
KeyError: 9
2025-08-03 16:57:03,293 - ERROR - Необработанное исключение: KeyError: 9
2025-08-03 16:57:03,293 - ERROR - Трассировка стека:
Traceback (most recent call last):
  File "C:\Users\Alex\Competitions_TT_v1.1\venv\Lib\site-packages\pandas\core\indexes\base.py", line 3812, in get_loc
    return self._engine.get_loc(casted_key)
           ~~~~~~~~~~~~~~~~~~~~^^^^^^^^^^^^
  File "pandas/_libs/index.pyx", line 167, in pandas._libs.index.IndexEngine.get_loc
  File "pandas/_libs/index.pyx", line 196, in pandas._libs.index.IndexEngine.get_loc
  File "pandas/_libs/hashtable_class_helper.pxi", line 2606, in pandas._libs.hashtable.Int64HashTable.get_item
  File "pandas/_libs/hashtable_class_helper.pxi", line 2630, in pandas._libs.hashtable.Int64HashTable.get_item
KeyError: 9

The above exception was the direct cause of the following exception:

Traceback (most recent call last):
  File "c:\Users\Alex\Competitions_TT_v1.1\main.py", line 165, in data
    return str(self._data[index.row()][index.column()])
               ~~~~~~~~~~^^^^^^^^^^^^^
  File "C:\Users\Alex\Competitions_TT_v1.1\venv\Lib\site-packages\pandas\core\frame.py", line 4107, in __getitem__
    indexer = self.columns.get_loc(key)
  File "C:\Users\Alex\Competitions_TT_v1.1\venv\Lib\site-packages\pandas\core\indexes\base.py", line 3819, in get_loc
    raise KeyError(key) from err
KeyError: 9
2025-08-03 16:57:03,300 - ERROR - Необработанное исключение: KeyError: 9
2025-08-03 16:57:03,301 - ERROR - Трассировка стека:
Traceback (most recent call last):
  File "C:\Users\Alex\Competitions_TT_v1.1\venv\Lib\site-packages\pandas\core\indexes\base.py", line 3812, in get_loc
    return self._engine.get_loc(casted_key)
           ~~~~~~~~~~~~~~~~~~~~^^^^^^^^^^^^
  File "pandas/_libs/index.pyx", line 167, in pandas._libs.index.IndexEngine.get_loc
  File "pandas/_libs/index.pyx", line 196, in pandas._libs.index.IndexEngine.get_loc
  File "pandas/_libs/hashtable_class_helper.pxi", line 2606, in pandas._libs.hashtable.Int64HashTable.get_item
  File "pandas/_libs/hashtable_class_helper.pxi", line 2630, in pandas._libs.hashtable.Int64HashTable.get_item
KeyError: 9

The above exception was the direct cause of the following exception:

Traceback (most recent call last):
  File "c:\Users\Alex\Competitions_TT_v1.1\main.py", line 167, in data
    val = str(self._data[index.row()][index.column()])
              ~~~~~~~~~~^^^^^^^^^^^^^
  File "C:\Users\Alex\Competitions_TT_v1.1\venv\Lib\site-packages\pandas\core\frame.py", line 4107, in __getitem__
    indexer = self.columns.get_loc(key)
  File "C:\Users\Alex\Competitions_TT_v1.1\venv\Lib\site-packages\pandas\core\indexes\base.py", line 3819, in get_loc
    raise KeyError(key) from err
KeyError: 9
2025-08-03 16:57:03,306 - ERROR - Необработанное исключение: KeyError: 9
2025-08-03 16:57:03,306 - ERROR - Трассировка стека:
Traceback (most recent call last):
  File "C:\Users\Alex\Competitions_TT_v1.1\venv\Lib\site-packages\pandas\core\indexes\base.py", line 3812, in get_loc
    return self._engine.get_loc(casted_key)
           ~~~~~~~~~~~~~~~~~~~~^^^^^^^^^^^^
  File "pandas/_libs/index.pyx", line 167, in pandas._libs.index.IndexEngine.get_loc
  File "pandas/_libs/index.pyx", line 196, in pandas._libs.index.IndexEngine.get_loc
  File "pandas/_libs/hashtable_class_helper.pxi", line 2606, in pandas._libs.hashtable.Int64HashTable.get_item
  File "pandas/_libs/hashtable_class_helper.pxi", line 2630, in pandas._libs.hashtable.Int64HashTable.get_item
KeyError: 9

The above exception was the direct cause of the following exception:

Traceback (most recent call last):
  File "c:\Users\Alex\Competitions_TT_v1.1\main.py", line 165, in data
    return str(self._data[index.row()][index.column()])
               ~~~~~~~~~~^^^^^^^^^^^^^
  File "C:\Users\Alex\Competitions_TT_v1.1\venv\Lib\site-packages\pandas\core\frame.py", line 4107, in __getitem__
    indexer = self.columns.get_loc(key)
  File "C:\Users\Alex\Competitions_TT_v1.1\venv\Lib\site-packages\pandas\core\indexes\base.py", line 3819, in get_loc
    raise KeyError(key) from err
KeyError: 9
2025-08-03 16:57:03,310 - ERROR - Необработанное исключение: KeyError: 9
2025-08-03 16:57:03,310 - ERROR - Трассировка стека:
Traceback (most recent call last):
  File "C:\Users\Alex\Competitions_TT_v1.1\venv\Lib\site-packages\pandas\core\indexes\base.py", line 3812, in get_loc
    return self._engine.get_loc(casted_key)
           ~~~~~~~~~~~~~~~~~~~~^^^^^^^^^^^^
  File "pandas/_libs/index.pyx", line 167, in pandas._libs.index.IndexEngine.get_loc
  File "pandas/_libs/index.pyx", line 196, in pandas._libs.index.IndexEngine.get_loc
  File "pandas/_libs/hashtable_class_helper.pxi", line 2606, in pandas._libs.hashtable.Int64HashTable.get_item
  File "pandas/_libs/hashtable_class_helper.pxi", line 2630, in pandas._libs.hashtable.Int64HashTable.get_item
KeyError: 9

The above exception was the direct cause of the following exception:

Traceback (most recent call last):
  File "c:\Users\Alex\Competitions_TT_v1.1\main.py", line 167, in data
    val = str(self._data[index.row()][index.column()])
              ~~~~~~~~~~^^^^^^^^^^^^^
  File "C:\Users\Alex\Competitions_TT_v1.1\venv\Lib\site-packages\pandas\core\frame.py", line 4107, in __getitem__
    indexer = self.columns.get_loc(key)
  File "C:\Users\Alex\Competitions_TT_v1.1\venv\Lib\site-packages\pandas\core\indexes\base.py", line 3819, in get_loc
    raise KeyError(key) from err
KeyError: 9
2025-08-03 16:57:03,321 - ERROR - Необработанное исключение: KeyError: 9
2025-08-03 16:57:03,321 - ERROR - Трассировка стека:
Traceback (most recent call last):
  File "C:\Users\Alex\Competitions_TT_v1.1\venv\Lib\site-packages\pandas\core\indexes\base.py", line 3812, in get_loc
    return self._engine.get_loc(casted_key)
           ~~~~~~~~~~~~~~~~~~~~^^^^^^^^^^^^
  File "pandas/_libs/index.pyx", line 167, in pandas._libs.index.IndexEngine.get_loc
  File "pandas/_libs/index.pyx", line 196, in pandas._libs.index.IndexEngine.get_loc
  File "pandas/_libs/hashtable_class_helper.pxi", line 2606, in pandas._libs.hashtable.Int64HashTable.get_item
  File "pandas/_libs/hashtable_class_helper.pxi", line 2630, in pandas._libs.hashtable.Int64HashTable.get_item
KeyError: 9

The above exception was the direct cause of the following exception:

Traceback (most recent call last):
  File "c:\Users\Alex\Competitions_TT_v1.1\main.py", line 165, in data
    return str(self._data[index.row()][index.column()])
               ~~~~~~~~~~^^^^^^^^^^^^^
  File "C:\Users\Alex\Competitions_TT_v1.1\venv\Lib\site-packages\pandas\core\frame.py", line 4107, in __getitem__
    indexer = self.columns.get_loc(key)
  File "C:\Users\Alex\Competitions_TT_v1.1\venv\Lib\site-packages\pandas\core\indexes\base.py", line 3819, in get_loc
    raise KeyError(key) from err
KeyError: 9
2025-08-03 16:57:03,326 - ERROR - Необработанное исключение: KeyError: 9
2025-08-03 16:57:03,326 - ERROR - Трассировка стека:
Traceback (most recent call last):
  File "C:\Users\Alex\Competitions_TT_v1.1\venv\Lib\site-packages\pandas\core\indexes\base.py", line 3812, in get_loc
    return self._engine.get_loc(casted_key)
           ~~~~~~~~~~~~~~~~~~~~^^^^^^^^^^^^
  File "pandas/_libs/index.pyx", line 167, in pandas._libs.index.IndexEngine.get_loc
  File "pandas/_libs/index.pyx", line 196, in pandas._libs.index.IndexEngine.get_loc
  File "pandas/_libs/hashtable_class_helper.pxi", line 2606, in pandas._libs.hashtable.Int64HashTable.get_item
  File "pandas/_libs/hashtable_class_helper.pxi", line 2630, in pandas._libs.hashtable.Int64HashTable.get_item
KeyError: 9

The above exception was the direct cause of the following exception:

Traceback (most recent call last):
  File "c:\Users\Alex\Competitions_TT_v1.1\main.py", line 167, in data
    val = str(self._data[index.row()][index.column()])
              ~~~~~~~~~~^^^^^^^^^^^^^
  File "C:\Users\Alex\Competitions_TT_v1.1\venv\Lib\site-packages\pandas\core\frame.py", line 4107, in __getitem__
    indexer = self.columns.get_loc(key)
  File "C:\Users\Alex\Competitions_TT_v1.1\venv\Lib\site-packages\pandas\core\indexes\base.py", line 3819, in get_loc
    raise KeyError(key) from err
KeyError: 9
2025-08-03 16:57:03,331 - ERROR - Необработанное исключение: KeyError: 9
2025-08-03 16:57:03,333 - ERROR - Трассировка стека:
Traceback (most recent call last):
  File "C:\Users\Alex\Competitions_TT_v1.1\venv\Lib\site-packages\pandas\core\indexes\base.py", line 3812, in get_loc
    return self._engine.get_loc(casted_key)
           ~~~~~~~~~~~~~~~~~~~~^^^^^^^^^^^^
  File "pandas/_libs/index.pyx", line 167, in pandas._libs.index.IndexEngine.get_loc
  File "pandas/_libs/index.pyx", line 196, in pandas._libs.index.IndexEngine.get_loc
  File "pandas/_libs/hashtable_class_helper.pxi", line 2606, in pandas._libs.hashtable.Int64HashTable.get_item
  File "pandas/_libs/hashtable_class_helper.pxi", line 2630, in pandas._libs.hashtable.Int64HashTable.get_item
KeyError: 9

The above exception was the direct cause of the following exception:

Traceback (most recent call last):
  File "c:\Users\Alex\Competitions_TT_v1.1\main.py", line 165, in data
    return str(self._data[index.row()][index.column()])
               ~~~~~~~~~~^^^^^^^^^^^^^
  File "C:\Users\Alex\Competitions_TT_v1.1\venv\Lib\site-packages\pandas\core\frame.py", line 4107, in __getitem__
    indexer = self.columns.get_loc(key)
  File "C:\Users\Alex\Competitions_TT_v1.1\venv\Lib\site-packages\pandas\core\indexes\base.py", line 3819, in get_loc
    raise KeyError(key) from err
KeyError: 9
2025-08-03 16:57:03,339 - ERROR - Необработанное исключение: KeyError: 9
2025-08-03 16:57:03,339 - ERROR - Трассировка стека:
Traceback (most recent call last):
  File "C:\Users\Alex\Competitions_TT_v1.1\venv\Lib\site-packages\pandas\core\indexes\base.py", line 3812, in get_loc
    return self._engine.get_loc(casted_key)
           ~~~~~~~~~~~~~~~~~~~~^^^^^^^^^^^^
  File "pandas/_libs/index.pyx", line 167, in pandas._libs.index.IndexEngine.get_loc
  File "pandas/_libs/index.pyx", line 196, in pandas._libs.index.IndexEngine.get_loc
  File "pandas/_libs/hashtable_class_helper.pxi", line 2606, in pandas._libs.hashtable.Int64HashTable.get_item
  File "pandas/_libs/hashtable_class_helper.pxi", line 2630, in pandas._libs.hashtable.Int64HashTable.get_item
KeyError: 9

The above exception was the direct cause of the following exception:

Traceback (most recent call last):
  File "c:\Users\Alex\Competitions_TT_v1.1\main.py", line 167, in data
    val = str(self._data[index.row()][index.column()])
              ~~~~~~~~~~^^^^^^^^^^^^^
  File "C:\Users\Alex\Competitions_TT_v1.1\venv\Lib\site-packages\pandas\core\frame.py", line 4107, in __getitem__
    indexer = self.columns.get_loc(key)
  File "C:\Users\Alex\Competitions_TT_v1.1\venv\Lib\site-packages\pandas\core\indexes\base.py", line 3819, in get_loc
    raise KeyError(key) from err
KeyError: 9
2025-08-03 16:57:03,342 - ERROR - Необработанное исключение: KeyError: 9
2025-08-03 16:57:03,344 - ERROR - Трассировка стека:
Traceback (most recent call last):
  File "C:\Users\Alex\Competitions_TT_v1.1\venv\Lib\site-packages\pandas\core\indexes\base.py", line 3812, in get_loc
    return self._engine.get_loc(casted_key)
           ~~~~~~~~~~~~~~~~~~~~^^^^^^^^^^^^
  File "pandas/_libs/index.pyx", line 167, in pandas._libs.index.IndexEngine.get_loc
  File "pandas/_libs/index.pyx", line 196, in pandas._libs.index.IndexEngine.get_loc
  File "pandas/_libs/hashtable_class_helper.pxi", line 2606, in pandas._libs.hashtable.Int64HashTable.get_item
  File "pandas/_libs/hashtable_class_helper.pxi", line 2630, in pandas._libs.hashtable.Int64HashTable.get_item
KeyError: 9

The above exception was the direct cause of the following exception:

Traceback (most recent call last):
  File "c:\Users\Alex\Competitions_TT_v1.1\main.py", line 165, in data
    return str(self._data[index.row()][index.column()])
               ~~~~~~~~~~^^^^^^^^^^^^^
  File "C:\Users\Alex\Competitions_TT_v1.1\venv\Lib\site-packages\pandas\core\frame.py", line 4107, in __getitem__
    indexer = self.columns.get_loc(key)
  File "C:\Users\Alex\Competitions_TT_v1.1\venv\Lib\site-packages\pandas\core\indexes\base.py", line 3819, in get_loc
    raise KeyError(key) from err
KeyError: 9
2025-08-03 16:57:03,354 - ERROR - Необработанное исключение: KeyError: 9
2025-08-03 16:57:03,354 - ERROR - Трассировка стека:
Traceback (most recent call last):
  File "C:\Users\Alex\Competitions_TT_v1.1\venv\Lib\site-packages\pandas\core\indexes\base.py", line 3812, in get_loc
    return self._engine.get_loc(casted_key)
           ~~~~~~~~~~~~~~~~~~~~^^^^^^^^^^^^
  File "pandas/_libs/index.pyx", line 167, in pandas._libs.index.IndexEngine.get_loc
  File "pandas/_libs/index.pyx", line 196, in pandas._libs.index.IndexEngine.get_loc
  File "pandas/_libs/hashtable_class_helper.pxi", line 2606, in pandas._libs.hashtable.Int64HashTable.get_item
  File "pandas/_libs/hashtable_class_helper.pxi", line 2630, in pandas._libs.hashtable.Int64HashTable.get_item
KeyError: 9

The above exception was the direct cause of the following exception:

Traceback (most recent call last):
  File "c:\Users\Alex\Competitions_TT_v1.1\main.py", line 167, in data
    val = str(self._data[index.row()][index.column()])
              ~~~~~~~~~~^^^^^^^^^^^^^
  File "C:\Users\Alex\Competitions_TT_v1.1\venv\Lib\site-packages\pandas\core\frame.py", line 4107, in __getitem__
    indexer = self.columns.get_loc(key)
  File "C:\Users\Alex\Competitions_TT_v1.1\venv\Lib\site-packages\pandas\core\indexes\base.py", line 3819, in get_loc
    raise KeyError(key) from err
KeyError: 9
2025-08-03 16:57:03,359 - ERROR - Необработанное исключение: KeyError: 9
2025-08-03 16:57:03,359 - ERROR - Трассировка стека:
Traceback (most recent call last):
  File "C:\Users\Alex\Competitions_TT_v1.1\venv\Lib\site-packages\pandas\core\indexes\base.py", line 3812, in get_loc
    return self._engine.get_loc(casted_key)
           ~~~~~~~~~~~~~~~~~~~~^^^^^^^^^^^^
  File "pandas/_libs/index.pyx", line 167, in pandas._libs.index.IndexEngine.get_loc
  File "pandas/_libs/index.pyx", line 196, in pandas._libs.index.IndexEngine.get_loc
  File "pandas/_libs/hashtable_class_helper.pxi", line 2606, in pandas._libs.hashtable.Int64HashTable.get_item
  File "pandas/_libs/hashtable_class_helper.pxi", line 2630, in pandas._libs.hashtable.Int64HashTable.get_item
KeyError: 9

The above exception was the direct cause of the following exception:

Traceback (most recent call last):
  File "c:\Users\Alex\Competitions_TT_v1.1\main.py", line 165, in data
    return str(self._data[index.row()][index.column()])
               ~~~~~~~~~~^^^^^^^^^^^^^
  File "C:\Users\Alex\Competitions_TT_v1.1\venv\Lib\site-packages\pandas\core\frame.py", line 4107, in __getitem__
    indexer = self.columns.get_loc(key)
  File "C:\Users\Alex\Competitions_TT_v1.1\venv\Lib\site-packages\pandas\core\indexes\base.py", line 3819, in get_loc
    raise KeyError(key) from err
KeyError: 9
2025-08-03 16:57:03,364 - ERROR - Необработанное исключение: KeyError: 9
2025-08-03 16:57:03,365 - ERROR - Трассировка стека:
Traceback (most recent call last):
  File "C:\Users\Alex\Competitions_TT_v1.1\venv\Lib\site-packages\pandas\core\indexes\base.py", line 3812, in get_loc
    return self._engine.get_loc(casted_key)
           ~~~~~~~~~~~~~~~~~~~~^^^^^^^^^^^^
  File "pandas/_libs/index.pyx", line 167, in pandas._libs.index.IndexEngine.get_loc
  File "pandas/_libs/index.pyx", line 196, in pandas._libs.index.IndexEngine.get_loc
  File "pandas/_libs/hashtable_class_helper.pxi", line 2606, in pandas._libs.hashtable.Int64HashTable.get_item
  File "pandas/_libs/hashtable_class_helper.pxi", line 2630, in pandas._libs.hashtable.Int64HashTable.get_item
KeyError: 9

The above exception was the direct cause of the following exception:

Traceback (most recent call last):
  File "c:\Users\Alex\Competitions_TT_v1.1\main.py", line 167, in data
    val = str(self._data[index.row()][index.column()])
              ~~~~~~~~~~^^^^^^^^^^^^^
  File "C:\Users\Alex\Competitions_TT_v1.1\venv\Lib\site-packages\pandas\core\frame.py", line 4107, in __getitem__
    indexer = self.columns.get_loc(key)
  File "C:\Users\Alex\Competitions_TT_v1.1\venv\Lib\site-packages\pandas\core\indexes\base.py", line 3819, in get_loc
    raise KeyError(key) from err
KeyError: 9
2025-08-03 16:57:03,371 - ERROR - Необработанное исключение: KeyError: 9
2025-08-03 16:57:03,371 - ERROR - Трассировка стека:
Traceback (most recent call last):
  File "C:\Users\Alex\Competitions_TT_v1.1\venv\Lib\site-packages\pandas\core\indexes\base.py", line 3812, in get_loc
    return self._engine.get_loc(casted_key)
           ~~~~~~~~~~~~~~~~~~~~^^^^^^^^^^^^
  File "pandas/_libs/index.pyx", line 167, in pandas._libs.index.IndexEngine.get_loc
  File "pandas/_libs/index.pyx", line 196, in pandas._libs.index.IndexEngine.get_loc
  File "pandas/_libs/hashtable_class_helper.pxi", line 2606, in pandas._libs.hashtable.Int64HashTable.get_item
  File "pandas/_libs/hashtable_class_helper.pxi", line 2630, in pandas._libs.hashtable.Int64HashTable.get_item
KeyError: 9

The above exception was the direct cause of the following exception:

Traceback (most recent call last):
  File "c:\Users\Alex\Competitions_TT_v1.1\main.py", line 165, in data
    return str(self._data[index.row()][index.column()])
               ~~~~~~~~~~^^^^^^^^^^^^^
  File "C:\Users\Alex\Competitions_TT_v1.1\venv\Lib\site-packages\pandas\core\frame.py", line 4107, in __getitem__
    indexer = self.columns.get_loc(key)
  File "C:\Users\Alex\Competitions_TT_v1.1\venv\Lib\site-packages\pandas\core\indexes\base.py", line 3819, in get_loc
    raise KeyError(key) from err
KeyError: 9
2025-08-03 16:57:03,375 - ERROR - Необработанное исключение: KeyError: 9
2025-08-03 16:57:03,375 - ERROR - Трассировка стека:
Traceback (most recent call last):
  File "C:\Users\Alex\Competitions_TT_v1.1\venv\Lib\site-packages\pandas\core\indexes\base.py", line 3812, in get_loc
    return self._engine.get_loc(casted_key)
           ~~~~~~~~~~~~~~~~~~~~^^^^^^^^^^^^
  File "pandas/_libs/index.pyx", line 167, in pandas._libs.index.IndexEngine.get_loc
  File "pandas/_libs/index.pyx", line 196, in pandas._libs.index.IndexEngine.get_loc
  File "pandas/_libs/hashtable_class_helper.pxi", line 2606, in pandas._libs.hashtable.Int64HashTable.get_item
  File "pandas/_libs/hashtable_class_helper.pxi", line 2630, in pandas._libs.hashtable.Int64HashTable.get_item
KeyError: 9

The above exception was the direct cause of the following exception:

Traceback (most recent call last):
  File "c:\Users\Alex\Competitions_TT_v1.1\main.py", line 167, in data
    val = str(self._data[index.row()][index.column()])
              ~~~~~~~~~~^^^^^^^^^^^^^
  File "C:\Users\Alex\Competitions_TT_v1.1\venv\Lib\site-packages\pandas\core\frame.py", line 4107, in __getitem__
    indexer = self.columns.get_loc(key)
  File "C:\Users\Alex\Competitions_TT_v1.1\venv\Lib\site-packages\pandas\core\indexes\base.py", line 3819, in get_loc
    raise KeyError(key) from err
KeyError: 9
2025-08-03 16:57:03,380 - ERROR - Необработанное исключение: KeyError: 9
2025-08-03 16:57:03,380 - ERROR - Трассировка стека:
Traceback (most recent call last):
  File "C:\Users\Alex\Competitions_TT_v1.1\venv\Lib\site-packages\pandas\core\indexes\base.py", line 3812, in get_loc
    return self._engine.get_loc(casted_key)
           ~~~~~~~~~~~~~~~~~~~~^^^^^^^^^^^^
  File "pandas/_libs/index.pyx", line 167, in pandas._libs.index.IndexEngine.get_loc
  File "pandas/_libs/index.pyx", line 196, in pandas._libs.index.IndexEngine.get_loc
  File "pandas/_libs/hashtable_class_helper.pxi", line 2606, in pandas._libs.hashtable.Int64HashTable.get_item
  File "pandas/_libs/hashtable_class_helper.pxi", line 2630, in pandas._libs.hashtable.Int64HashTable.get_item
KeyError: 9

The above exception was the direct cause of the following exception:

Traceback (most recent call last):
  File "c:\Users\Alex\Competitions_TT_v1.1\main.py", line 165, in data
    return str(self._data[index.row()][index.column()])
               ~~~~~~~~~~^^^^^^^^^^^^^
  File "C:\Users\Alex\Competitions_TT_v1.1\venv\Lib\site-packages\pandas\core\frame.py", line 4107, in __getitem__
    indexer = self.columns.get_loc(key)
  File "C:\Users\Alex\Competitions_TT_v1.1\venv\Lib\site-packages\pandas\core\indexes\base.py", line 3819, in get_loc
    raise KeyError(key) from err
KeyError: 9
