2025-08-03 12:03:15,047 - ERROR - Необработанное исключение: AttributeError: 'str' object has no attribute 'close'
2025-08-03 12:03:15,049 - ERROR - Трассировка стека:
Traceback (most recent call last):
  File "c:\Users\Alex\Competitions_TT_v1.1\main.py", line 759, in log_file_read
    f.close()
    ^^^^^^^
AttributeError: 'str' object has no attribute 'close'
