2025-08-10 10:25:02,136 - ERROR - Необработанное исключение: UnboundLocalError: cannot access local variable 'table_db' where it is not associated with a value
2025-08-10 10:25:02,138 - ERROR - Трассировка стека:
Traceback (most recent call last):
  File "c:\Users\Alex\Competitions_TT_v1.2\main.py", line 1312, in new
    db_r(gamer)
    ~~~~^^^^^^^
  File "c:\Users\Alex\Competitions_TT_v1.2\main.py", line 1551, in db_r
    load_listR_in_db(fname, table_db)
                            ^^^^^^^^
UnboundLocalError: cannot access local variable 'table_db' where it is not associated with a value
