2025-08-04 09:32:03,611 - ERROR - Необработанное исключение: TTFError: Can't open file "C:\Users\Alex\Competitions_TT_v1.1\font\DejaVuSans.ttf"
2025-08-04 09:32:03,611 - ERROR - Трассировка стека:
Traceback (most recent call last):
  File "C:\Users\Alex\Competitions_TT_v1.1\venv\Lib\site-packages\reportlab\lib\utils.py", line 523, in open_for_read
    return open_for_read_by_name(name,mode)
  File "C:\Users\Alex\Competitions_TT_v1.1\venv\Lib\site-packages\reportlab\lib\utils.py", line 463, in open_for_read_by_name
    return open(name,mode)
FileNotFoundError: [Errno 2] No such file or directory: 'C:\\Users\\Alex\\Competitions_TT_v1.1\\font\\DejaVuSans.ttf'

During handling of the above exception, another exception occurred:

Traceback (most recent call last):
  File "C:\Users\Alex\Competitions_TT_v1.1\venv\Lib\site-packages\reportlab\lib\utils.py", line 530, in open_for_read
    return BytesIO((datareader if name[:5].lower()=='data:' else rlUrlRead)(name))
                   ~~~~~~~~~~~~~~~~~~~~~~~~~~~~~~~~~~~~~~~~~~~~~~~~~~~~~~~~^^^^^^
  File "C:\Users\Alex\Competitions_TT_v1.1\venv\Lib\site-packages\reportlab\lib\utils.py", line 476, in rlUrlRead
    return urlopen(name).read()
           ~~~~~~~^^^^^^
  File "C:\Users\Alex\AppData\Local\Programs\Python\Python313\Lib\urllib\request.py", line 189, in urlopen
    return opener.open(url, data, timeout)
           ~~~~~~~~~~~^^^^^^^^^^^^^^^^^^^^
  File "C:\Users\Alex\AppData\Local\Programs\Python\Python313\Lib\urllib\request.py", line 489, in open
    response = self._open(req, data)
  File "C:\Users\Alex\AppData\Local\Programs\Python\Python313\Lib\urllib\request.py", line 511, in _open
    return self._call_chain(self.handle_open, 'unknown',
           ~~~~~~~~~~~~~~~~^^^^^^^^^^^^^^^^^^^^^^^^^^^^^
                            'unknown_open', req)
                            ^^^^^^^^^^^^^^^^^^^^
  File "C:\Users\Alex\AppData\Local\Programs\Python\Python313\Lib\urllib\request.py", line 466, in _call_chain
    result = func(*args)
  File "C:\Users\Alex\AppData\Local\Programs\Python\Python313\Lib\urllib\request.py", line 1395, in unknown_open
    raise URLError('unknown url type: %s' % type)
urllib.error.URLError: <urlopen error unknown url type: c>

During handling of the above exception, another exception occurred:

Traceback (most recent call last):
  File "C:\Users\Alex\Competitions_TT_v1.1\venv\Lib\site-packages\reportlab\pdfbase\ttfonts.py", line 159, in TTFOpenFile
    f = open_for_read(fn,'rb')
  File "C:\Users\Alex\Competitions_TT_v1.1\venv\Lib\site-packages\reportlab\lib\utils.py", line 534, in open_for_read
    return open_for_read(name,mode)
  File "C:\Users\Alex\Competitions_TT_v1.1\venv\Lib\site-packages\reportlab\lib\utils.py", line 532, in open_for_read
    raise IOError('Cannot open resource "%s"' % name)
OSError: Cannot open resource "C:\Users\Alex\Competitions_TT_v1.1\font\DejaVuSans.ttf"

During handling of the above exception, another exception occurred:

Traceback (most recent call last):
  File "c:\Users\Alex\Competitions_TT_v1.1\main.py", line 129, in <module>
    pdfmetrics.registerFont(TTFont('DejaVuSans', os.path.join(outpath, 'DejaVuSans.ttf')))
                            ~~~~~~^^^^^^^^^^^^^^^^^^^^^^^^^^^^^^^^^^^^^^^^^^^^^^^^^^^^^^^
  File "C:\Users\Alex\Competitions_TT_v1.1\venv\Lib\site-packages\reportlab\pdfbase\ttfonts.py", line 1207, in __init__
    self.face = TTFontFace(filename, validate=validate, subfontIndex=subfontIndex)
                ~~~~~~~~~~^^^^^^^^^^^^^^^^^^^^^^^^^^^^^^^^^^^^^^^^^^^^^^^^^^^^^^^^
  File "C:\Users\Alex\Competitions_TT_v1.1\venv\Lib\site-packages\reportlab\pdfbase\ttfonts.py", line 1088, in __init__
    TTFontFile.__init__(self, filename, validate=validate, subfontIndex=subfontIndex)
    ~~~~~~~~~~~~~~~~~~~^^^^^^^^^^^^^^^^^^^^^^^^^^^^^^^^^^^^^^^^^^^^^^^^^^^^^^^^^^^^^^
  File "C:\Users\Alex\Competitions_TT_v1.1\venv\Lib\site-packages\reportlab\pdfbase\ttfonts.py", line 447, in __init__
    TTFontParser.__init__(self, file, validate=validate,subfontIndex=subfontIndex)
    ~~~~~~~~~~~~~~~~~~~~~^^^^^^^^^^^^^^^^^^^^^^^^^^^^^^^^^^^^^^^^^^^^^^^^^^^^^^^^^
  File "C:\Users\Alex\Competitions_TT_v1.1\venv\Lib\site-packages\reportlab\pdfbase\ttfonts.py", line 183, in __init__
    self.readFile(file)
    ~~~~~~~~~~~~~^^^^^^
  File "C:\Users\Alex\Competitions_TT_v1.1\venv\Lib\site-packages\reportlab\pdfbase\ttfonts.py", line 259, in readFile
    self.filename, f = TTFOpenFile(f)
                       ~~~~~~~~~~~^^^
  File "C:\Users\Alex\Competitions_TT_v1.1\venv\Lib\site-packages\reportlab\pdfbase\ttfonts.py", line 169, in TTFOpenFile
    raise TTFError('Can\'t open file "%s"' % fn)
reportlab.pdfbase.ttfonts.TTFError: Can't open file "C:\Users\Alex\Competitions_TT_v1.1\font\DejaVuSans.ttf"
