2025-08-13 21:05:23,124 - ERROR - Необработанное исключение: OperationalError: (1054, "Unknown column 't1.sex' in 'field list'")
2025-08-13 21:05:23,126 - ERROR - Трассировка стека:
Traceback (most recent call last):
  File "c:\Users\Alex\Competitions_TT_v1.2\venv\Lib\site-packages\peewee.py", line 3322, in execute_sql
    cursor.execute(sql, params or ())
    ~~~~~~~~~~~~~~^^^^^^^^^^^^^^^^^^^
  File "c:\Users\Alex\Competitions_TT_v1.2\venv\Lib\site-packages\pymysql\cursors.py", line 153, in execute
    result = self._query(query)
  File "c:\Users\Alex\Competitions_TT_v1.2\venv\Lib\site-packages\pymysql\cursors.py", line 322, in _query
    conn.query(q)
    ~~~~~~~~~~^^^
  File "c:\Users\Alex\Competitions_TT_v1.2\venv\Lib\site-packages\pymysql\connections.py", line 563, in query
    self._affected_rows = self._read_query_result(unbuffered=unbuffered)
                          ~~~~~~~~~~~~~~~~~~~~~~~^^^^^^^^^^^^^^^^^^^^^^^
  File "c:\Users\Alex\Competitions_TT_v1.2\venv\Lib\site-packages\pymysql\connections.py", line 825, in _read_query_result
    result.read()
    ~~~~~~~~~~~^^
  File "c:\Users\Alex\Competitions_TT_v1.2\venv\Lib\site-packages\pymysql\connections.py", line 1199, in read
    first_packet = self.connection._read_packet()
  File "c:\Users\Alex\Competitions_TT_v1.2\venv\Lib\site-packages\pymysql\connections.py", line 775, in _read_packet
    packet.raise_for_error()
    ~~~~~~~~~~~~~~~~~~~~~~^^
  File "c:\Users\Alex\Competitions_TT_v1.2\venv\Lib\site-packages\pymysql\protocol.py", line 219, in raise_for_error
    err.raise_mysql_exception(self._data)
    ~~~~~~~~~~~~~~~~~~~~~~~~~^^^^^^^^^^^^
  File "c:\Users\Alex\Competitions_TT_v1.2\venv\Lib\site-packages\pymysql\err.py", line 150, in raise_mysql_exception
    raise errorclass(errno, errval)
pymysql.err.OperationalError: (1054, "Unknown column 't1.sex' in 'field list'")

During handling of the above exception, another exception occurred:

Traceback (most recent call last):
  File "c:\Users\Alex\Competitions_TT_v1.2\main.py", line 1053, in system_clear
    system_clear()
    ~~~~~~~~~~~~^^
  File "c:\Users\Alex\Competitions_TT_v1.2\main.py", line 4879, in system_clear
    for i in game_lists:
             ^^^^^^^^^^
  File "c:\Users\Alex\Competitions_TT_v1.2\venv\Lib\site-packages\peewee.py", line 7285, in __iter__
    self.execute()
    ~~~~~~~~~~~~^^
  File "c:\Users\Alex\Competitions_TT_v1.2\venv\Lib\site-packages\peewee.py", line 2036, in inner
    return method(self, database, *args, **kwargs)
  File "c:\Users\Alex\Competitions_TT_v1.2\venv\Lib\site-packages\peewee.py", line 2107, in execute
    return self._execute(database)
           ~~~~~~~~~~~~~^^^^^^^^^^
  File "c:\Users\Alex\Competitions_TT_v1.2\venv\Lib\site-packages\peewee.py", line 2280, in _execute
    cursor = database.execute(self)
  File "c:\Users\Alex\Competitions_TT_v1.2\venv\Lib\site-packages\peewee.py", line 3330, in execute
    return self.execute_sql(sql, params)
           ~~~~~~~~~~~~~~~~^^^^^^^^^^^^^
  File "c:\Users\Alex\Competitions_TT_v1.2\venv\Lib\site-packages\peewee.py", line 3320, in execute_sql
    with __exception_wrapper__:
         ^^^^^^^^^^^^^^^^^^^^^
  File "c:\Users\Alex\Competitions_TT_v1.2\venv\Lib\site-packages\peewee.py", line 3088, in __exit__
    reraise(new_type, new_type(exc_value, *exc_args), traceback)
    ~~~~~~~^^^^^^^^^^^^^^^^^^^^^^^^^^^^^^^^^^^^^^^^^^^^^^^^^^^^^
  File "c:\Users\Alex\Competitions_TT_v1.2\venv\Lib\site-packages\peewee.py", line 196, in reraise
    raise value.with_traceback(tb)
  File "c:\Users\Alex\Competitions_TT_v1.2\venv\Lib\site-packages\peewee.py", line 3322, in execute_sql
    cursor.execute(sql, params or ())
    ~~~~~~~~~~~~~~^^^^^^^^^^^^^^^^^^^
  File "c:\Users\Alex\Competitions_TT_v1.2\venv\Lib\site-packages\pymysql\cursors.py", line 153, in execute
    result = self._query(query)
  File "c:\Users\Alex\Competitions_TT_v1.2\venv\Lib\site-packages\pymysql\cursors.py", line 322, in _query
    conn.query(q)
    ~~~~~~~~~~^^^
  File "c:\Users\Alex\Competitions_TT_v1.2\venv\Lib\site-packages\pymysql\connections.py", line 563, in query
    self._affected_rows = self._read_query_result(unbuffered=unbuffered)
                          ~~~~~~~~~~~~~~~~~~~~~~~^^^^^^^^^^^^^^^^^^^^^^^
  File "c:\Users\Alex\Competitions_TT_v1.2\venv\Lib\site-packages\pymysql\connections.py", line 825, in _read_query_result
    result.read()
    ~~~~~~~~~~~^^
  File "c:\Users\Alex\Competitions_TT_v1.2\venv\Lib\site-packages\pymysql\connections.py", line 1199, in read
    first_packet = self.connection._read_packet()
  File "c:\Users\Alex\Competitions_TT_v1.2\venv\Lib\site-packages\pymysql\connections.py", line 775, in _read_packet
    packet.raise_for_error()
    ~~~~~~~~~~~~~~~~~~~~~~^^
  File "c:\Users\Alex\Competitions_TT_v1.2\venv\Lib\site-packages\pymysql\protocol.py", line 219, in raise_for_error
    err.raise_mysql_exception(self._data)
    ~~~~~~~~~~~~~~~~~~~~~~~~~^^^^^^^^^^^^
  File "c:\Users\Alex\Competitions_TT_v1.2\venv\Lib\site-packages\pymysql\err.py", line 150, in raise_mysql_exception
    raise errorclass(errno, errval)
peewee.OperationalError: (1054, "Unknown column 't1.sex' in 'field list'")
