2025-08-04 16:46:20,244 - ERROR - Необработанное исключение: IntegrityError: (1452, 'Cannot add or update a child row: a foreign key constraint fails (`mysql_db`.`players_double`, CONSTRAINT `players_double_ibfk_1` FOREIGN KEY (`title_id`) REFERENCES `titles` (`id`))')
2025-08-04 16:46:20,247 - ERROR - Трассировка стека:
Traceback (most recent call last):
  File "C:\Users\Alex\Competitions_TT_v1.1\venv\Lib\site-packages\peewee.py", line 3322, in execute_sql
    cursor.execute(sql, params or ())
    ~~~~~~~~~~~~~~^^^^^^^^^^^^^^^^^^^
  File "C:\Users\Alex\Competitions_TT_v1.1\venv\Lib\site-packages\pymysql\cursors.py", line 153, in execute
    result = self._query(query)
  File "C:\Users\Alex\Competitions_TT_v1.1\venv\Lib\site-packages\pymysql\cursors.py", line 322, in _query
    conn.query(q)
    ~~~~~~~~~~^^^
  File "C:\Users\Alex\Competitions_TT_v1.1\venv\Lib\site-packages\pymysql\connections.py", line 563, in query
    self._affected_rows = self._read_query_result(unbuffered=unbuffered)
                          ~~~~~~~~~~~~~~~~~~~~~~~^^^^^^^^^^^^^^^^^^^^^^^
  File "C:\Users\Alex\Competitions_TT_v1.1\venv\Lib\site-packages\pymysql\connections.py", line 825, in _read_query_result
    result.read()
    ~~~~~~~~~~~^^
  File "C:\Users\Alex\Competitions_TT_v1.1\venv\Lib\site-packages\pymysql\connections.py", line 1199, in read
    first_packet = self.connection._read_packet()
  File "C:\Users\Alex\Competitions_TT_v1.1\venv\Lib\site-packages\pymysql\connections.py", line 775, in _read_packet
    packet.raise_for_error()
    ~~~~~~~~~~~~~~~~~~~~~~^^
  File "C:\Users\Alex\Competitions_TT_v1.1\venv\Lib\site-packages\pymysql\protocol.py", line 219, in raise_for_error
    err.raise_mysql_exception(self._data)
    ~~~~~~~~~~~~~~~~~~~~~~~~~^^^^^^^^^^^^
  File "C:\Users\Alex\Competitions_TT_v1.1\venv\Lib\site-packages\pymysql\err.py", line 150, in raise_mysql_exception
    raise errorclass(errno, errval)
pymysql.err.IntegrityError: (1452, 'Cannot add or update a child row: a foreign key constraint fails (`mysql_db`.`players_double`, CONSTRAINT `players_double_ibfk_1` FOREIGN KEY (`title_id`) REFERENCES `titles` (`id`))')

During handling of the above exception, another exception occurred:

Traceback (most recent call last):
  File "c:\Users\Alex\Competitions_TT_v1.1\main.py", line 18156, in add_double_player_to_list
    double_vid=vid).save()
                    ~~~~^^
  File "C:\Users\Alex\Competitions_TT_v1.1\venv\Lib\site-packages\peewee.py", line 6958, in save
    pk = self.insert(**field_dict).execute()
  File "C:\Users\Alex\Competitions_TT_v1.1\venv\Lib\site-packages\peewee.py", line 2036, in inner
    return method(self, database, *args, **kwargs)
  File "C:\Users\Alex\Competitions_TT_v1.1\venv\Lib\site-packages\peewee.py", line 2107, in execute
    return self._execute(database)
           ~~~~~~~~~~~~~^^^^^^^^^^
  File "C:\Users\Alex\Competitions_TT_v1.1\venv\Lib\site-packages\peewee.py", line 2912, in _execute
    return super(Insert, self)._execute(database)
           ~~~~~~~~~~~~~~~~~~~~~~~~~~~~^^^^^^^^^^
  File "C:\Users\Alex\Competitions_TT_v1.1\venv\Lib\site-packages\peewee.py", line 2625, in _execute
    cursor = database.execute(self)
  File "C:\Users\Alex\Competitions_TT_v1.1\venv\Lib\site-packages\peewee.py", line 3330, in execute
    return self.execute_sql(sql, params)
           ~~~~~~~~~~~~~~~~^^^^^^^^^^^^^
  File "C:\Users\Alex\Competitions_TT_v1.1\venv\Lib\site-packages\peewee.py", line 3320, in execute_sql
    with __exception_wrapper__:
         ^^^^^^^^^^^^^^^^^^^^^
  File "C:\Users\Alex\Competitions_TT_v1.1\venv\Lib\site-packages\peewee.py", line 3088, in __exit__
    reraise(new_type, new_type(exc_value, *exc_args), traceback)
    ~~~~~~~^^^^^^^^^^^^^^^^^^^^^^^^^^^^^^^^^^^^^^^^^^^^^^^^^^^^^
  File "C:\Users\Alex\Competitions_TT_v1.1\venv\Lib\site-packages\peewee.py", line 196, in reraise
    raise value.with_traceback(tb)
  File "C:\Users\Alex\Competitions_TT_v1.1\venv\Lib\site-packages\peewee.py", line 3322, in execute_sql
    cursor.execute(sql, params or ())
    ~~~~~~~~~~~~~~^^^^^^^^^^^^^^^^^^^
  File "C:\Users\Alex\Competitions_TT_v1.1\venv\Lib\site-packages\pymysql\cursors.py", line 153, in execute
    result = self._query(query)
  File "C:\Users\Alex\Competitions_TT_v1.1\venv\Lib\site-packages\pymysql\cursors.py", line 322, in _query
    conn.query(q)
    ~~~~~~~~~~^^^
  File "C:\Users\Alex\Competitions_TT_v1.1\venv\Lib\site-packages\pymysql\connections.py", line 563, in query
    self._affected_rows = self._read_query_result(unbuffered=unbuffered)
                          ~~~~~~~~~~~~~~~~~~~~~~~^^^^^^^^^^^^^^^^^^^^^^^
  File "C:\Users\Alex\Competitions_TT_v1.1\venv\Lib\site-packages\pymysql\connections.py", line 825, in _read_query_result
    result.read()
    ~~~~~~~~~~~^^
  File "C:\Users\Alex\Competitions_TT_v1.1\venv\Lib\site-packages\pymysql\connections.py", line 1199, in read
    first_packet = self.connection._read_packet()
  File "C:\Users\Alex\Competitions_TT_v1.1\venv\Lib\site-packages\pymysql\connections.py", line 775, in _read_packet
    packet.raise_for_error()
    ~~~~~~~~~~~~~~~~~~~~~~^^
  File "C:\Users\Alex\Competitions_TT_v1.1\venv\Lib\site-packages\pymysql\protocol.py", line 219, in raise_for_error
    err.raise_mysql_exception(self._data)
    ~~~~~~~~~~~~~~~~~~~~~~~~~^^^^^^^^^^^^
  File "C:\Users\Alex\Competitions_TT_v1.1\venv\Lib\site-packages\pymysql\err.py", line 150, in raise_mysql_exception
    raise errorclass(errno, errval)
peewee.IntegrityError: (1452, 'Cannot add or update a child row: a foreign key constraint fails (`mysql_db`.`players_double`, CONSTRAINT `players_double_ibfk_1` FOREIGN KEY (`title_id`) REFERENCES `titles` (`id`))')
